Workbook

Sheet 使用說明
A1: 訂單自動產出模板 v3.13
A3: 步驟 1 | B3: ERP 匯出裝櫃通知單
A4: 步驟 2 | B4: ★ 先按「裝櫃單號」排序
A5: 步驟 3 | B5: 複製全部資料（含標題列）
A6: 步驟 4 | B6: 貼到「ERP資料」分頁 A1
A7: 步驟 5 | B7: 查看繳庫本、生管本-平板、生管本-捲筒
A9: v3.13 更新 | B9: 新增「100張客戶」對照表 — 特殊備註自動標「100張」+提芬尼綠
B10: 右側欄位：寬/長/件數(自動) + 狀態(下拉) + 訂購日期 + 備註
B11: 狀態下拉選項：未訂 / 已訂 / 已到貨
A13: 核心邏輯 | B13: 件數用「迄-起+1」計算，過濾 ERP 實蹈
B14: 同尺寸自動合併，件數加總
A16: 手動填欄位 | B16: 雙生、特殊備註、生產配對指示、已出數量、✓
B17: 紙管規格：對照表沒有的客戶才需手動填
A19: 色彩圖例
B20: 深藍底 = 標題列
B21: 淡藍底 = 訂單標題行 / 對照表自動帶入
B22: 綠色底 = 自動計算
B23: 橘黃底 = 手動填寫
B24: 亮黃底 = 雙生棧板提醒

Sheet ERP資料
A1: 裝櫃通知單號 | B1: 結關日 | C1: 起 | D1: 迄 | E1: 材質 | F1: 基重 | G1: 寬 | H1: 長 | I1: KG/件 | J1: 數量 | K1: 單位 | L1: 件數 | M1: 淨重 | N1: 毛重/件 | O1: 束/件 | P1: 單價 | Q1: 美金/MT | R1: 毛重 | S1: 客戶 | T1: 產品別 | U1: 交易條件 | V1: 目的地

Sheet 紙管對照表
A1: 客戶代號 | B1: 客戶名稱 | C1: 管徑 | D1: 備註
A2: E146 | B2: 虹育 | C2: 6"
A3: E293 | B3: 康發 | C3: 6"
A4: E343 | B4: 聰棋 | C4: 6"
A5: E361 | B5: KOUFU | C5: 6"
A6: E397 | B6: 合亨 | C6: 6"
A7: G007 | B7: Eastern | C7: 6" | D7: 114年7月起 改用 6" 紙管
A8: G114 | B8: PTACCORD | C8: 6" | D8: 202509 起改用 6" (原 12")
A9: G518 | B9: ALI | C9: 6"
A10: G533 | B10: CROWN | C10: 6"
A11: G580 | B11: Prominen | C11: 6"
A12: G751 | B12: STARKSON | C12: 6"
A13: G755 | B13: PRECISIO | C13: 6"
A14: G759 | B14: WILLIAMS | C14: 6"
A15: E357 | B15: 丞益 | C15: 12"
A16: E373 | B16: 東旭-廣銘 | C16: 12"
A17: G003 | B17: Fong YEE | C17: 12"
A18: G009 | B18: IPG | C18: 12"
A19: G025 | B19: ELANTEC | C19: 12"
A20: G035 | B20: EASTSUN | C20: 12"
... A29: G781 | B29: TM TAN | C29: 12"
A30: G801 | B30: CV Surya | C30: - | D30: 已倒閉
A33: ★ 新增客戶時，直接在此表加一列（客戶代號 4 碼 + 管徑），生管本-捲筒會自動帶入

Sheet 100張客戶
A1: 客戶代號 | B1: 客戶名稱 | C1: 備註
A2: G003 | B2: Fong YEE
A3: G007 | B3: Eastern
A4: G025 | B4: ELANTEC
A5: G037 | B5: OVOL
A6: G107 | B6: STARLITE
A7: G137 | B7: BANGKOK
A8: E384 | B8: 台灣丸紅
A9: G401 | B9: LimTong
A10: G513 | B10: MOHSIN
A11: G525 | B11: ELAHI
A12: G703 | B12: VIVAR
A13: G713 | B13: TIONGTAT
... A22: G523 | B22: SAMI P.
A25: ★ 此表的客戶 + 基重 270 或 300 GSM → 自動在生管本標「100張」

Sheet 輔助計算
A1: row | B1: _key | C1: _first | D1: _sumqty | E1: _outrow_jk | F1: _outrow_pb | G1: _outrow_cj | H1: _rowqty
A2: 2 | B2: =IF(ERP資料!A2="","",ERP資料!A2&"|"&ERP資料!E2&"|"&ERP資料!F2&"|"&ERP資料!G2&"|"&ERP資料!H2&"|"&ERP資料!O2) | C2: =IF(B2="",0,IF(COUNTIF(B$2:B1,B2)=0,1,0)) | D2: =IF(B2="",0,SUMIFS($H$2:$H$801,$B$2:$B$801,B2)) | E2: =IF(AND(C2=1, TRIM(ERP資料!T2)="平板"), 1, 0) | F2: =IF(AND(C2=1, TRIM(ERP資料!T2)="平板"), 1, 0) | G2: =IF(AND(C2=1, TRIM(ERP資料!T2)="捲筒"), 1, 0) | H2: =IF(OR(ERP資料!C2="",ERP資料!D2=""),0,ERP資料!D2-ERP資料!C2+1)
A3: 3 | B3: =IF(ERP資料!A3="","",ERP資料!A3&"|"&ERP資料!E3&"|"&ERP資料!F3&"|"&ERP資料!G3&"|"&ERP資料!H3&"|"&ERP資料!O3) | C3: =IF(B3="",0,IF(COUNTIF(B$2:B2,B3)=0,1,0)) | D3: =IF(B3="",0,SUMIFS($H$2:$H$801,$B$2:$B$801,B3)) | E3: =IF(NOT(AND(C3=1, TRIM(ERP資料!T3)="平板")), 0, IF(MAX(E$2:E2)=0, 1, IF(ERP資料!A3=INDEX(ERP資料!$A$2:$A2, MATCH(MAX(E$2:E2), E$2:E2, 0)), MAX(E$2:E2)+1, MAX(E$2:E2)+2))) | F3: =IF(NOT(AND(C3=1, TRIM(ERP資料!T3)="平板")), 0, IF(MAX(F$2:F2)=0, 1, IF(ERP資料!A3=INDEX(ERP資料!$A$2:$A2, MATCH(MAX(F$2:F2), F$2:F2, 0)), MAX(F$2:F2)+1, MAX(F$2:F2)+2))) | G3: =IF(NOT(AND(C3=1, TRIM(ERP資料!T3)="捲筒")), 0, IF(MAX(G$2:G2)=0, 1, IF(ERP資料!A3=INDEX(ERP資料!$A$2:$A2, MATCH(MAX(G$2:G2), G$2:G2, 0)), MAX(G$2:G2)+1, MAX(G$2:G2)+2))) | H3: =IF(OR(ERP資料!C3="",ERP資料!D3=""),0,ERP資料!D3-ERP資料!C3+1)
A4: 4 | B4: =IF(ERP資料!A4="","",ERP資料!A4&"|"&ERP資料!E4&"|"&ERP資料!F4&"|"&ERP資料!G4&"|"&ERP資料!H4&"|"&ERP資料!O4) | C4: =IF(B4="",0,IF(COUNTIF(B$2:B3,B4)=0,1,0)) | D4: =IF(B4="",0,SUMIFS($H$2:$H$801,$B$2:$B$801,B4)) | E4: =IF(NOT(AND(C4=1, TRIM(ERP資料!T4)="平板")), 0, IF(MAX(E$2:E3)=0, 1, IF(ERP資料!A4=INDEX(ERP資料!$A$2:$A3, MATCH(MAX(E$2:E3), E$2:E3, 0)), MAX(E$2:E3)+1, MAX(E$2:E3)+2))) | F4: =IF(NOT(AND(C4=1, TRIM(ERP資料!T4)="平板")), 0, IF(MAX(F$2:F3)=0, 1, IF(ERP資料!A4=INDEX(ERP資料!$A$2:$A3, MATCH(MAX(F$2:F3), F$2:F3, 0)), MAX(F$2:F3)+1, MAX(F$2:F3)+2))) | G4: =IF(NOT(AND(C4=1, TRIM(ERP資料!T4)="捲筒")), 0, IF(MAX(G$2:G3)=0, 1, IF(ERP資料!A4=INDEX(ERP資料!$A$2:$A3, MATCH(MAX(G$2:G3), G$2:G3, 0)), MAX(G$2:G3)+1, MAX(G$2:G3)+2))) | H4: =IF(OR(ERP資料!C4="",ERP資料!D4=""),0,ERP資料!D4-ERP資料!C4+1)
A5: 5 | B5: =IF(ERP資料!A5="","",ERP資料!A5&"|"&ERP資料!E5&"|"&ERP資料!F5&"|"&ERP資料!G5&"|"&ERP資料!H5&"|"&ERP資料!O5) | C5: =IF(B5="",0,IF(COUNTIF(B$2:B4,B5)=0,1,0)) | D5: =IF(B5="",0,SUMIFS($H$2:$H$801,$B$2:$B$801,B5)) | E5: =IF(NOT(AND(C5=1, TRIM(ERP資料!T5)="平板")), 0, IF(MAX(E$2:E4)=0, 1, IF(ERP資料!A5=INDEX(ERP資料!$A$2:$A4, MATCH(MAX(E$2:E4), E$2:E4, 0)), MAX(E$2:E4)+1, MAX(E$2:E4)+2))) | F5: =IF(NOT(AND(C5=1, TRIM(ERP資料!T5)="平板")), 0, IF(MAX(F$2:F4)=0, 1, IF(ERP資料!A5=INDEX(ERP資料!$A$2:$A4, MATCH(MAX(F$2:F4), F$2:F4, 0)), MAX(F$2:F4)+1, MAX(F$2:F4)+2))) | G5: =IF(NOT(AND(C5=1, TRIM(ERP資料!T5)="捲筒")), 0, IF(MAX(G$2:G4)=0, 1, IF(ERP資料!A5=INDEX(ERP資料!$A$2:$A4, MATCH(MAX(G$2:G4), G$2:G4, 0)), MAX(G$2:G4)+1, MAX(G$2:G4)+2))) | H5: =IF(OR(ERP資料!C5="",ERP資料!D5=""),0,ERP資料!D5-ERP資料!C5+1)
A6: 6 | B6: =IF(ERP資料!A6="","",ERP資料!A6&"|"&ERP資料!E6&"|"&ERP資料!F6&"|"&ERP資料!G6&"|"&ERP資料!H6&"|"&ERP資料!O6) | C6: =IF(B6="",0,IF(COUNTIF(B$2:B5,B6)=0,1,0)) | D6: =IF(B6="",0,SUMIFS($H$2:$H$801,$B$2:$B$801,B6)) | E6: =IF(NOT(AND(C6=1, TRIM(ERP資料!T6)="平板")), 0, IF(MAX(E$2:E5)=0, 1, IF(ERP資料!A6=INDEX(ERP資料!$A$2:$A5, MATCH(MAX(E$2:E5), E$2:E5, 0)), MAX(E$2:E5)+1, MAX(E$2:E5)+2))) | F6: =IF(NOT(AND(C6=1, TRIM(ERP資料!T6)="平板")), 0, IF(MAX(F$2:F5)=0, 1, IF(ERP資料!A6=INDEX(ERP資料!$A$2:$A5, MATCH(MAX(F$2:F5), F$2:F5, 0)), MAX(F$2:F5)+1, MAX(F$2:F5)+2))) | G6: =IF(NOT(AND(C6=1, TRIM(ERP資料!T6)="捲筒")), 0, IF(MAX(G$2:G5)=0, 1, IF(ERP資料!A6=INDEX(ERP資料!$A$2:$A5, MATCH(MAX(G$2:G5), G$2:G5, 0)), MAX(G$2:G5)+1, MAX(G$2:G5)+2))) | H6: =IF(OR(ERP資料!C6="",ERP資料!D6=""),0,ERP資料!D6-ERP資料!C6+1)
A7: 7 | B7: =IF(ERP資料!A7="","",ERP資料!A7&"|"&ERP資料!E7&"|"&ERP資料!F7&"|"&ERP資料!G7&"|"&ERP資料!H7&"|"&ERP資料!O7) | C7: =IF(B7="",0,IF(COUNTIF(B$2:B6,B7)=0,1,0)) | D7: =IF(B7="",0,SUMIFS($H$2:$H$801,$B$2:$B$801,B7)) | E7: =IF(NOT(AND(C7=1, TRIM(ERP資料!T7)="平板")), 0, IF(MAX(E$2:E6)=0, 1, IF(ERP資料!A7=INDEX(ERP資料!$A$2:$A6, MATCH(MAX(E$2:E6), E$2:E6, 0)), MAX(E$2:E6)+1, MAX(E$2:E6)+2))) | F7: =IF(NOT(AND(C7=1, TRIM(ERP資料!T7)="平板")), 0, IF(MAX(F$2:F6)=0, 1, IF(ERP資料!A7=INDEX(ERP資料!$A$2:$A6, MATCH(MAX(F$2:F6), F$2:F6, 0)), MAX(F$2:F6)+1, MAX(F$2:F6)+2))) | G7: =IF(NOT(AND(C7=1, TRIM(ERP資料!T7)="捲筒")), 0, IF(MAX(G$2:G6)=0, 1, IF(ERP資料!A7=INDEX(ERP資料!$A$2:$A6, MATCH(MAX(G$2:G6), G$2:G6, 0)), MAX(G$2:G6)+1, MAX(G$2:G6)+2))) | H7: =IF(OR(ERP資料!C7="",ERP資料!D7=""),0,ERP資料!D7-ERP資料!C7+1)
A8: 8 | B8: =IF(ERP資料!A8="","",ERP資料!A8&"|"&ERP資料!E8&"|"&ERP資料!F8&"|"&ERP資料!G8&"|"&ERP資料!H8&"|"&ERP資料!O8) | C8: =IF(B8="",0,IF(COUNTIF(B$2:B7,B8)=0,1,0)) | D8: =IF(B8="",0,SUMIFS($H$2:$H$801,$B$2:$B$801,B8)) | E8: =IF(NOT(AND(C8=1, TRIM(ERP資料!T8)="平板")), 0, IF(MAX(E$2:E7)=0, 1, IF(ERP資料!A8=INDEX(ERP資料!$A$2:$A7, MATCH(MAX(E$2:E7), E$2:E7, 0)), MAX(E$2:E7)+1, MAX(E$2:E7)+2))) | F8: =IF(NOT(AND(C8=1, TRIM(ERP資料!T8)="平板")), 0, IF(MAX(F$2:F7)=0, 1, IF(ERP資料!A8=INDEX(ERP資料!$A$2:$A7, MATCH(MAX(F$2:F7), F$2:F7, 0)), MAX(F$2:F7)+1, MAX(F$2:F7)+2))) | G8: =IF(NOT(AND(C8=1, TRIM(ERP資料!T8)="捲筒")), 0, IF(MAX(G$2:G7)=0, 1, IF(ERP資料!A8=INDEX(ERP資料!$A$2:$A7, MATCH(MAX(G$2:G7), G$2:G7, 0)), MAX(G$2:G7)+1, MAX(G$2:G7)+2))) | H8: =IF(OR(ERP資料!C8="",ERP資料!D8=""),0,ERP資料!D8-ERP資料!C8+1)
A9: 9 | B9: =IF(ERP資料!A9="","",ERP資料!A9&"|"&ERP資料!E9&"|"&ERP資料!F9&"|"&ERP資料!G9&"|"&ERP資料!H9&"|"&ERP資料!O9) | C9: =IF(B9="",0,IF(COUNTIF(B$2:B8,B9)=0,1,0)) | D9: =IF(B9="",0,SUMIFS($H$2:$H$801,$B$2:$B$801,B9)) | E9: =IF(NOT(AND(C9=1, TRIM(ERP資料!T9)="平板")), 0, IF(MAX(E$2:E8)=0, 1, IF(ERP資料!A9=INDEX(ERP資料!$A$2:$A8, MATCH(MAX(E$2:E8), E$2:E8, 0)), MAX(E$2:E8)+1, MAX(E$2:E8)+2))) | F9: =IF(NOT(AND(C9=1, TRIM(ERP資料!T9)="平板")), 0, IF(MAX(F$2:F8)=0, 1, IF(ERP資料!A9=INDEX(ERP資料!$A$2:$A8, MATCH(MAX(F$2:F8), F$2:F8, 0)), MAX(F$2:F8)+1, MAX(F$2:F8)+2))) | G9: =IF(NOT(AND(C9=1, TRIM(ERP資料!T9)="捲筒")), 0, IF(MAX(G$2:G8)=0, 1, IF(ERP資料!A9=INDEX(ERP資料!$A$2:$A8, MATCH(MAX(G$2:G8), G$2:G8, 0)), MAX(G$2:G8)+1, MAX(G$2:G8)+2))) | H9: =IF(OR(ERP資料!C9="",ERP資料!D9=""),0,ERP資料!D9-ERP資料!C9+1)
A10: 10 | B10: =IF(ERP資料!A10="","",ERP資料!A10&"|"&ERP資料!E10&"|"&ERP資料!F10&"|"&ERP資料!G10&"|"&ERP資料!H10&"|"&ERP資料!O10) | C10: =IF(B10="",0,IF(COUNTIF(B$2:B9,B10)=0,1,0)) | D10: =IF(B10="",0,SUMIFS($H$2:$H$801,$B$2:$B$801,B10)) | E10: =IF(NOT(AND(C10=1, TRIM(ERP資料!T10)="平板")), 0, IF(MAX(E$2:E9)=0, 1, IF(ERP資料!A10=INDEX(ERP資料!$A$2:$A9, MATCH(MAX(E$2:E9), E$2:E9, 0)), MAX(E$2:E9)+1, MAX(E$2:E9)+2))) | F10: =IF(NOT(AND(C10=1, TRIM(ERP資料!T10)="平板")), 0, IF(MAX(F$2:F9)=0, 1, IF(ERP資料!A10=INDEX(ERP資料!$A$2:$A9, MATCH(MAX(F$2:F9), F$2:F9, 0)), MAX(F$2:F9)+1, MAX(F$2:F9)+2))) | G10: =IF(NOT(AND(C10=1, TRIM(ERP資料!T10)="捲筒")), 0, IF(MAX(G$2:G9)=0, 1, IF(ERP資料!A10=INDEX(ERP資料!$A$2:$A9, MATCH(MAX(G$2:G9), G$2:G9, 0)), MAX(G$2:G9)+1, MAX(G$2:G9)+2))) | H10: =IF(OR(ERP資料!C10="",ERP資料!D10=""),0,ERP資料!D10-ERP資料!C10+1)
A11: 11 | B11: =IF(ERP資料!A11="","",ERP資料!A11&"|"&ERP資料!E11&"|"&ERP資料!F11&"|"&ERP資料!G11&"|"&ERP資料!H11&"|"&ERP資料!O11) | C11: =IF(B11="",0,IF(COUNTIF(B$2:B10,B11)=0,1,0)) | D11: =IF(B11="",0,SUMIFS($H$2:$H$801,$B$2:$B$801,B11)) | E11: =IF(NOT(AND(C11=1, TRIM(ERP資料!T11)="平板")), 0, IF(MAX(E$2:E10)=0, 1, IF(ERP資料!A11=INDEX(ERP資料!$A$2:$A10, MATCH(MAX(E$2:E10), E$2:E10, 0)), MAX(E$2:E10)+1, MAX(E$2:E10)+2))) | F11: =IF(NOT(AND(C11=1, TRIM(ERP資料!T11)="平板")), 0, IF(MAX(F$2:F10)=0, 1, IF(ERP資料!A11=INDEX(ERP資料!$A$2:$A10, MATCH(MAX(F$2:F10), F$2:F10, 0)), MAX(F$2:F10)+1, MAX(F$2:F10)+2))) | G11: =IF(NOT(AND(C11=1, TRIM(ERP資料!T11)="捲筒")), 0, IF(MAX(G$2:G10)=0, 1, IF(ERP資料!A11=INDEX(ERP資料!$A$2:$A10, MATCH(MAX(G$2:G10), G$2:G10, 0)), MAX(G$2:G10)+1, MAX(G$2:G10)+2))) | H11: =IF(OR(ERP資料!C11="",ERP資料!D11=""),0,ERP資料!D11-ERP資料!C11+1)
A12: 12 | B12: =IF(ERP資料!A12="","",ERP資料!A12&"|"&ERP資料!E12&"|"&ERP資料!F12&"|"&ERP資料!G12&"|"&ERP資料!H12&"|"&ERP資料!O12) | C12: =IF(B12="",0,IF(COUNTIF(B$2:B11,B12)=0,1,0)) | D12: =IF(B12="",0,SUMIFS($H$2:$H$801,$B$2:$B$801,B12)) | E12: =IF(NOT(AND(C12=1, TRIM(ERP資料!T12)="平板")), 0, IF(MAX(E$2:E11)=0, 1, IF(ERP資料!A12=INDEX(ERP資料!$A$2:$A11, MATCH(MAX(E$2:E11), E$2:E11, 0)), MAX(E$2:E11)+1, MAX(E$2:E11)+2))) | F12: =IF(NOT(AND(C12=1, TRIM(ERP資料!T12)="平板")), 0, IF(MAX(F$2:F11)=0, 1, IF(ERP資料!A12=INDEX(ERP資料!$A$2:$A11, MATCH(MAX(F$2:F11), F$2:F11, 0)), MAX(F$2:F11)+1, MAX(F$2:F11)+2))) | G12: =IF(NOT(AND(C12=1, TRIM(ERP資料!T12)="捲筒")), 0, IF(MAX(G$2:G11)=0, 1, IF(ERP資料!A12=INDEX(ERP資料!$A$2:$A11, MATCH(MAX(G$2:G11), G$2:G11, 0)), MAX(G$2:G11)+1, MAX(G$2:G11)+2))) | H12: =IF(OR(ERP資料!C12="",ERP資料!D12=""),0,ERP資料!D12-ERP資料!C12+1)
A13: 13 | B13: =IF(ERP資料!A13="","",ERP資料!A13&"|"&ERP資料!E13&"|"&ERP資料!F13&"|"&ERP資料!G13&"|"&ERP資料!H13&"|"&ERP資料!O13) | C13: =IF(B13="",0,IF(COUNTIF(B$2:B12,B13)=0,1,0)) | D13: =IF(B13="",0,SUMIFS($H$2:$H$801,$B$2:$B$801,B13)) | E13: =IF(NOT(AND(C13=1, TRIM(ERP資料!T13)="平板")), 0, IF(MAX(E$2:E12)=0, 1, IF(ERP資料!A13=INDEX(ERP資料!$A$2:$A12, MATCH(MAX(E$2:E12), E$2:E12, 0)), MAX(E$2:E12)+1, MAX(E$2:E12)+2))) | F13: =IF(NOT(AND(C13=1, TRIM(ERP資料!T13)="平板")), 0, IF(MAX(F$2:F12)=0, 1, IF(ERP資料!A13=INDEX(ERP資料!$A$2:$A12, MATCH(MAX(F$2:F12), F$2:F12, 0)), MAX(F$2:F12)+1, MAX(F$2:F12)+2))) | G13: =IF(NOT(AND(C13=1, TRIM(ERP資料!T13)="捲筒")), 0, IF(MAX(G$2:G12)=0, 1, IF(ERP資料!A13=INDEX(ERP資料!$A$2:$A12, MATCH(MAX(G$2:G12), G$2:G12, 0)), MAX(G$2:G12)+1, MAX(G$2:G12)+2))) | H13: =IF(OR(ERP資料!C13="",ERP資料!D13=""),0,ERP資料!D13-ERP資料!C13+1)
A14: 14 | B14: =IF(ERP資料!A14="","",ERP資料!A14&"|"&ERP資料!E14&"|"&ERP資料!F14&"|"&ERP資料!G14&"|"&ERP資料!H14&"|"&ERP資料!O14) | C14: =IF(B14="",0,IF(COUNTIF(B$2:B13,B14)=0,1,0)) | D14: =IF(B14="",0,SUMIFS($H$2:$H$801,$B$2:$B$801,B14)) | E14: =IF(NOT(AND(C14=1, TRIM(ERP資料!T14)="平板")), 0, IF(MAX(E$2:E13)=0, 1, IF(ERP資料!A14=INDEX(ERP資料!$A$2:$A13, MATCH(MAX(E$2:E13), E$2:E13, 0)), MAX(E$2:E13)+1, MAX(E$2:E13)+2))) | F14: =IF(NOT(AND(C14=1, TRIM(ERP資料!T14)="平板")), 0, IF(MAX(F$2:F13)=0, 1, IF(ERP資料!A14=INDEX(ERP資料!$A$2:$A13, MATCH(MAX(F$2:F13), F$2:F13, 0)), MAX(F$2:F13)+1, MAX(F$2:F13)+2))) | G14: =IF(NOT(AND(C14=1, TRIM(ERP資料!T14)="捲筒")), 0, IF(MAX(G$2:G13)=0, 1, IF(ERP資料!A14=INDEX(ERP資料!$A$2:$A13, MATCH(MAX(G$2:G13), G$2:G13, 0)), MAX(G$2:G13)+1, MAX(G$2:G13)+2))) | H14: =IF(OR(ERP資料!C14="",ERP資料!D14=""),0,ERP資料!D14-ERP資料!C14+1)
... A801: 801 | B801: =IF(ERP資料!A801="","",ERP資料!A801&"|"&ERP資料!E801&"|"&ERP資料!F801&"|"&ERP資料!G801&"|"&ERP資料!H801&"|"&ERP資料!O801) | C801: =IF(B801="",0,IF(COUNTIF(B$2:B800,B801)=0,1,0)) | D801: =IF(B801="",0,SUMIFS($H$2:$H$801,$B$2:$B$801,B801)) | E801: =IF(NOT(AND(C801=1, TRIM(ERP資料!T801)="平板")), 0, IF(MAX(E$2:E800)=0, 1, IF(ERP資料!A801=INDEX(ERP資料!$A$2:$A800, MATCH(MAX(E$2:E800), E$2:E800, 0)), MAX(E$2:E800)+1, MAX(E$2:E800)+2))) | F801: =IF(NOT(AND(C801=1, TRIM(ERP資料!T801)="平板")), 0, IF(MAX(F$2:F800)=0, 1, IF(ERP資料!A801=INDEX(ERP資料!$A$2:$A800, MATCH(MAX(F$2:F800), F$2:F800, 0)), MAX(F$2:F800)+1, MAX(F$2:F800)+2))) | G801: =IF(NOT(AND(C801=1, TRIM(ERP資料!T801)="捲筒")), 0, IF(MAX(G$2:G800)=0, 1, IF(ERP資料!A801=INDEX(ERP資料!$A$2:$A800, MATCH(MAX(G$2:G800), G$2:G800, 0)), MAX(G$2:G800)+1, MAX(G$2:G800)+2))) | H801: =IF(OR(ERP資料!C801="",ERP資料!D801=""),0,ERP資料!D801-ERP資料!C801+1)

Sheet 繳庫本
A1: 結關日 | B1: 裝櫃單號 | C1: 客戶 | D1: 紙類 | E1: 基重 | F1: 寬 | G1: 長 | H1: 件數 | I1: 束/件 | J1: 總束數 (自動) | K1: 已出數量 | L1: 備註 | M1: ✓
A2: =IFERROR(IF(INDEX(ERP資料!$B:$B, (MATCH(1, 輔助計算!$E$2:$E$801, 0)+1))="","",INDEX(ERP資料!$B:$B, (MATCH(1, 輔助計算!$E$2:$E$801, 0)+1))), "") | B2: =IFERROR(IF(INDEX(ERP資料!$A:$A, (MATCH(1, 輔助計算!$E$2:$E$801, 0)+1))="","",INDEX(ERP資料!$A:$A, (MATCH(1, 輔助計算!$E$2:$E$801, 0)+1))), "") | C2: =IFERROR(IF(INDEX(ERP資料!$S:$S, (MATCH(1, 輔助計算!$E$2:$E$801, 0)+1))="","",INDEX(ERP資料!$S:$S, (MATCH(1, 輔助計算!$E$2:$E$801, 0)+1))), "") | D2: =IFERROR(IF(INDEX(ERP資料!$E:$E, (MATCH(1, 輔助計算!$E$2:$E$801, 0)+1))="","",TRIM(INDEX(ERP資料!$E:$E, (MATCH(1, 輔助計算!$E$2:$E$801, 0)+1)))), "") | E2: =IFERROR(IF(INDEX(ERP資料!$F:$F, (MATCH(1, 輔助計算!$E$2:$E$801, 0)+1))="","",INDEX(ERP資料!$F:$F, (MATCH(1, 輔助計算!$E$2:$E$801, 0)+1))), "") | F2: =IFERROR(IF(INDEX(ERP資料!$G:$G, (MATCH(1, 輔助計算!$E$2:$E$801, 0)+1))="","",INDEX(ERP資料!$G:$G, (MATCH(1, 輔助計算!$E$2:$E$801, 0)+1))), "") | G2: =IFERROR(IF(INDEX(ERP資料!$H:$H, (MATCH(1, 輔助計算!$E$2:$E$801, 0)+1))="","",INDEX(ERP資料!$H:$H, (MATCH(1, 輔助計算!$E$2:$E$801, 0)+1))), "") | H2: =IFERROR(INDEX(輔助計算!$D:$D, (MATCH(1, 輔助計算!$E$2:$E$801, 0)+1)), "") | I2: =IFERROR(IF(INDEX(ERP資料!$O:$O, (MATCH(1, 輔助計算!$E$2:$E$801, 0)+1))="","",INDEX(ERP資料!$O:$O, (MATCH(1, 輔助計算!$E$2:$E$801, 0)+1))), "") | J2: =IFERROR(IF(INDEX(輔助計算!$D:$D,(MATCH(1, 輔助計算!$E$2:$E$801, 0)+1))="","",INDEX(輔助計算!$D:$D,(MATCH(1, 輔助計算!$E$2:$E$801, 0)+1))*INDEX(ERP資料!$O:$O,(MATCH(1, 輔助計算!$E$2:$E$801, 0)+1))), "")
A3: =IFERROR(IF(INDEX(ERP資料!$B:$B, (MATCH(2, 輔助計算!$E$2:$E$801, 0)+1))="","",INDEX(ERP資料!$B:$B, (MATCH(2, 輔助計算!$E$2:$E$801, 0)+1))), "") | B3: =IFERROR(IF(INDEX(ERP資料!$A:$A, (MATCH(2, 輔助計算!$E$2:$E$801, 0)+1))="","",INDEX(ERP資料!$A:$A, (MATCH(2, 輔助計算!$E$2:$E$801, 0)+1))), "") | C3: =IFERROR(IF(INDEX(ERP資料!$S:$S, (MATCH(2, 輔助計算!$E$2:$E$801, 0)+1))="","",INDEX(ERP資料!$S:$S, (MATCH(2, 輔助計算!$E$2:$E$801, 0)+1))), "") | D3: =IFERROR(IF(INDEX(ERP資料!$E:$E, (MATCH(2, 輔助計算!$E$2:$E$801, 0)+1))="","",TRIM(INDEX(ERP資料!$E:$E, (MATCH(2, 輔助計算!$E$2:$E$801, 0)+1)))), "") | E3: =IFERROR(IF(INDEX(ERP資料!$F:$F, (MATCH(2, 輔助計算!$E$2:$E$801, 0)+1))="","",INDEX(ERP資料!$F:$F, (MATCH(2, 輔助計算!$E$2:$E$801, 0)+1))), "") | F3: =IFERROR(IF(INDEX(ERP資料!$G:$G, (MATCH(2, 輔助計算!$E$2:$E$801, 0)+1))="","",INDEX(ERP資料!$G:$G, (MATCH(2, 輔助計算!$E$2:$E$801, 0)+1))), "") | G3: =IFERROR(IF(INDEX(ERP資料!$H:$H, (MATCH(2, 輔助計算!$E$2:$E$801, 0)+1))="","",INDEX(ERP資料!$H:$H, (MATCH(2, 輔助計算!$E$2:$E$801, 0)+1))), "") | H3: =IFERROR(INDEX(輔助計算!$D:$D, (MATCH(2, 輔助計算!$E$2:$E$801, 0)+1)), "") | I3: =IFERROR(IF(INDEX(ERP資料!$O:$O, (MATCH(2, 輔助計算!$E$2:$E$801, 0)+1))="","",INDEX(ERP資料!$O:$O, (MATCH(2, 輔助計算!$E$2:$E$801, 0)+1))), "") | J3: =IFERROR(IF(INDEX(輔助計算!$D:$D,(MATCH(2, 輔助計算!$E$2:$E$801, 0)+1))="","",INDEX(輔助計算!$D:$D,(MATCH(2, 輔助計算!$E$2:$E$801, 0)+1))*INDEX(ERP資料!$O:$O,(MATCH(2, 輔助計算!$E$2:$E$801, 0)+1))), "")
A4: =IFERROR(IF(INDEX(ERP資料!$B:$B, (MATCH(3, 輔助計算!$E$2:$E$801, 0)+1))="","",INDEX(ERP資料!$B:$B, (MATCH(3, 輔助計算!$E$2:$E$801, 0)+1))), "") | B4: =IFERROR(IF(INDEX(ERP資料!$A:$A, (MATCH(3, 輔助計算!$E$2:$E$801, 0)+1))="","",INDEX(ERP資料!$A:$A, (MATCH(3, 輔助計算!$E$2:$E$801, 0)+1))), "") | C4: =IFERROR(IF(INDEX(ERP資料!$S:$S, (MATCH(3, 輔助計算!$E$2:$E$801, 0)+1))="","",INDEX(ERP資料!$S:$S, (MATCH(3, 輔助計算!$E$2:$E$801, 0)+1))), "") | D4: =IFERROR(IF(INDEX(ERP資料!$E:$E, (MATCH(3, 輔助計算!$E$2:$E$801, 0)+1))="","",TRIM(INDEX(ERP資料!$E:$E, (MATCH(3, 輔助計算!$E$2:$E$801, 0)+1)))), "") | E4: =IFERROR(IF(INDEX(ERP資料!$F:$F, (MATCH(3, 輔助計算!$E$2:$E$801, 0)+1))="","",INDEX(ERP資料!$F:$F, (MATCH(3, 輔助計算!$E$2:$E$801, 0)+1))), "") | F4: =IFERROR(IF(INDEX(ERP資料!$G:$G, (MATCH(3, 輔助計算!$E$2:$E$801, 0)+1))="","",INDEX(ERP資料!$G:$G, (MATCH(3, 輔助計算!$E$2:$E$801, 0)+1))), "") | G4: =IFERROR(IF(INDEX(ERP資料!$H:$H, (MATCH(3, 輔助計算!$E$2:$E$801, 0)+1))="","",INDEX(ERP資料!$H:$H, (MATCH(3, 輔助計算!$E$2:$E$801, 0)+1))), "") | H4: =IFERROR(INDEX(輔助計算!$D:$D, (MATCH(3, 輔助計算!$E$2:$E$801, 0)+1)), "") | I4: =IFERROR(IF(INDEX(ERP資料!$O:$O, (MATCH(3, 輔助計算!$E$2:$E$801, 0)+1))="","",INDEX(ERP資料!$O:$O, (MATCH(3, 輔助計算!$E$2:$E$801, 0)+1))), "") | J4: =IFERROR(IF(INDEX(輔助計算!$D:$D,(MATCH(3, 輔助計算!$E$2:$E$801, 0)+1))="","",INDEX(輔助計算!$D:$D,(MATCH(3, 輔助計算!$E$2:$E$801, 0)+1))*INDEX(ERP資料!$O:$O,(MATCH(3, 輔助計算!$E$2:$E$801, 0)+1))), "")
A5: =IFERROR(IF(INDEX(ERP資料!$B:$B, (MATCH(4, 輔助計算!$E$2:$E$801, 0)+1))="","",INDEX(ERP資料!$B:$B, (MATCH(4, 輔助計算!$E$2:$E$801, 0)+1))), "") | B5: =IFERROR(IF(INDEX(ERP資料!$A:$A, (MATCH(4, 輔助計算!$E$2:$E$801, 0)+1))="","",INDEX(ERP資料!$A:$A, (MATCH(4, 輔助計算!$E$2:$E$801, 0)+1))), "") | C5: =IFERROR(IF(INDEX(ERP資料!$S:$S, (MATCH(4, 輔助計算!$E$2:$E$801, 0)+1))="","",INDEX(ERP資料!$S:$S, (MATCH(4, 輔助計算!$E$2:$E$801, 0)+1))), "") | D5: =IFERROR(IF(INDEX(ERP資料!$E:$E, (MATCH(4, 輔助計算!$E$2:$E$801, 0)+1))="","",TRIM(INDEX(ERP資料!$E:$E, (MATCH(4, 輔助計算!$E$2:$E$801, 0)+1)))), "") | E5: =IFERROR(IF(INDEX(ERP資料!$F:$F, (MATCH(4, 輔助計算!$E$2:$E$801, 0)+1))="","",INDEX(ERP資料!$F:$F, (MATCH(4, 輔助計算!$E$2:$E$801, 0)+1))), "") | F5: =IFERROR(IF(INDEX(ERP資料!$G:$G, (MATCH(4, 輔助計算!$E$2:$E$801, 0)+1))="","",INDEX(ERP資料!$G:$G, (MATCH(4, 輔助計算!$E$2:$E$801, 0)+1))), "") | G5: =IFERROR(IF(INDEX(ERP資料!$H:$H, (MATCH(4, 輔助計算!$E$2:$E$801, 0)+1))="","",INDEX(ERP資料!$H:$H, (MATCH(4, 輔助計算!$E$2:$E$801, 0)+1))), "") | H5: =IFERROR(INDEX(輔助計算!$D:$D, (MATCH(4, 輔助計算!$E$2:$E$801, 0)+1)), "") | I5: =IFERROR(IF(INDEX(ERP資料!$O:$O, (MATCH(4, 輔助計算!$E$2:$E$801, 0)+1))="","",INDEX(ERP資料!$O:$O, (MATCH(4, 輔助計算!$E$2:$E$801, 0)+1))), "") | J5: =IFERROR(IF(INDEX(輔助計算!$D:$D,(MATCH(4, 輔助計算!$E$2:$E$801, 0)+1))="","",INDEX(輔助計算!$D:$D,(MATCH(4, 輔助計算!$E$2:$E$801, 0)+1))*INDEX(ERP資料!$O:$O,(MATCH(4, 輔助計算!$E$2:$E$801, 0)+1))), "")
A6: =IFERROR(IF(INDEX(ERP資料!$B:$B, (MATCH(5, 輔助計算!$E$2:$E$801, 0)+1))="","",INDEX(ERP資料!$B:$B, (MATCH(5, 輔助計算!$E$2:$E$801, 0)+1))), "") | B6: =IFERROR(IF(INDEX(ERP資料!$A:$A, (MATCH(5, 輔助計算!$E$2:$E$801, 0)+1))="","",INDEX(ERP資料!$A:$A, (MATCH(5, 輔助計算!$E$2:$E$801, 0)+1))), "") | C6: =IFERROR(IF(INDEX(ERP資料!$S:$S, (MATCH(5, 輔助計算!$E$2:$E$801, 0)+1))="","",INDEX(ERP資料!$S:$S, (MATCH(5, 輔助計算!$E$2:$E$801, 0)+1))), "") | D6: =IFERROR(IF(INDEX(ERP資料!$E:$E, (MATCH(5, 輔助計算!$E$2:$E$801, 0)+1))="","",TRIM(INDEX(ERP資料!$E:$E, (MATCH(5, 輔助計算!$E$2:$E$801, 0)+1)))), "") | E6: =IFERROR(IF(INDEX(ERP資料!$F:$F, (MATCH(5, 輔助計算!$E$2:$E$801, 0)+1))="","",INDEX(ERP資料!$F:$F, (MATCH(5, 輔助計算!$E$2:$E$801, 0)+1))), "") | F6: =IFERROR(IF(INDEX(ERP資料!$G:$G, (MATCH(5, 輔助計算!$E$2:$E$801, 0)+1))="","",INDEX(ERP資料!$G:$G, (MATCH(5, 輔助計算!$E$2:$E$801, 0)+1))), "") | G6: =IFERROR(IF(INDEX(ERP資料!$H:$H, (MATCH(5, 輔助計算!$E$2:$E$801, 0)+1))="","",INDEX(ERP資料!$H:$H, (MATCH(5, 輔助計算!$E$2:$E$801, 0)+1))), "") | H6: =IFERROR(INDEX(輔助計算!$D:$D, (MATCH(5, 輔助計算!$E$2:$E$801, 0)+1)), "") | I6: =IFERROR(IF(INDEX(ERP資料!$O:$O, (MATCH(5, 輔助計算!$E$2:$E$801, 0)+1))="","",INDEX(ERP資料!$O:$O, (MATCH(5, 輔助計算!$E$2:$E$801, 0)+1))), "") | J6: =IFERROR(IF(INDEX(輔助計算!$D:$D,(MATCH(5, 輔助計算!$E$2:$E$801, 0)+1))="","",INDEX(輔助計算!$D:$D,(MATCH(5, 輔助計算!$E$2:$E$801, 0)+1))*INDEX(ERP資料!$O:$O,(MATCH(5, 輔助計算!$E$2:$E$801, 0)+1))), "")
A7: =IFERROR(IF(INDEX(ERP資料!$B:$B, (MATCH(6, 輔助計算!$E$2:$E$801, 0)+1))="","",INDEX(ERP資料!$B:$B, (MATCH(6, 輔助計算!$E$2:$E$801, 0)+1))), "") | B7: =IFERROR(IF(INDEX(ERP資料!$A:$A, (MATCH(6, 輔助計算!$E$2:$E$801, 0)+1))="","",INDEX(ERP資料!$A:$A, (MATCH(6, 輔助計算!$E$2:$E$801, 0)+1))), "") | C7: =IFERROR(IF(INDEX(ERP資料!$S:$S, (MATCH(6, 輔助計算!$E$2:$E$801, 0)+1))="","",INDEX(ERP資料!$S:$S, (MATCH(6, 輔助計算!$E$2:$E$801, 0)+1))), "") | D7: =IFERROR(IF(INDEX(ERP資料!$E:$E, (MATCH(6, 輔助計算!$E$2:$E$801, 0)+1))="","",TRIM(INDEX(ERP資料!$E:$E, (MATCH(6, 輔助計算!$E$2:$E$801, 0)+1)))), "") | E7: =IFERROR(IF(INDEX(ERP資料!$F:$F, (MATCH(6, 輔助計算!$E$2:$E$801, 0)+1))="","",INDEX(ERP資料!$F:$F, (MATCH(6, 輔助計算!$E$2:$E$801, 0)+1))), "") | F7: =IFERROR(IF(INDEX(ERP資料!$G:$G, (MATCH(6, 輔助計算!$E$2:$E$801, 0)+1))="","",INDEX(ERP資料!$G:$G, (MATCH(6, 輔助計算!$E$2:$E$801, 0)+1))), "") | G7: =IFERROR(IF(INDEX(ERP資料!$H:$H, (MATCH(6, 輔助計算!$E$2:$E$801, 0)+1))="","",INDEX(ERP資料!$H:$H, (MATCH(6, 輔助計算!$E$2:$E$801, 0)+1))), "") | H7: =IFERROR(INDEX(輔助計算!$D:$D, (MATCH(6, 輔助計算!$E$2:$E$801, 0)+1)), "") | I7: =IFERROR(IF(INDEX(ERP資料!$O:$O, (MATCH(6, 輔助計算!$E$2:$E$801, 0)+1))="","",INDEX(ERP資料!$O:$O, (MATCH(6, 輔助計算!$E$2:$E$801, 0)+1))), "") | J7: =IFERROR(IF(INDEX(輔助計算!$D:$D,(MATCH(6, 輔助計算!$E$2:$E$801, 0)+1))="","",INDEX(輔助計算!$D:$D,(MATCH(6, 輔助計算!$E$2:$E$801, 0)+1))*INDEX(ERP資料!$O:$O,(MATCH(6, 輔助計算!$E$2:$E$801, 0)+1))), "")
A8: =IFERROR(IF(INDEX(ERP資料!$B:$B, (MATCH(7, 輔助計算!$E$2:$E$801, 0)+1))="","",INDEX(ERP資料!$B:$B, (MATCH(7, 輔助計算!$E$2:$E$801, 0)+1))), "") | B8: =IFERROR(IF(INDEX(ERP資料!$A:$A, (MATCH(7, 輔助計算!$E$2:$E$801, 0)+1))="","",INDEX(ERP資料!$A:$A, (MATCH(7, 輔助計算!$E$2:$E$801, 0)+1))), "") | C8: =IFERROR(IF(INDEX(ERP資料!$S:$S, (MATCH(7, 輔助計算!$E$2:$E$801, 0)+1))="","",INDEX(ERP資料!$S:$S, (MATCH(7, 輔助計算!$E$2:$E$801, 0)+1))), "") | D8: =IFERROR(IF(INDEX(ERP資料!$E:$E, (MATCH(7, 輔助計算!$E$2:$E$801, 0)+1))="","",TRIM(INDEX(ERP資料!$E:$E, (MATCH(7, 輔助計算!$E$2:$E$801, 0)+1)))), "") | E8: =IFERROR(IF(INDEX(ERP資料!$F:$F, (MATCH(7, 輔助計算!$E$2:$E$801, 0)+1))="","",INDEX(ERP資料!$F:$F, (MATCH(7, 輔助計算!$E$2:$E$801, 0)+1))), "") | F8: =IFERROR(IF(INDEX(ERP資料!$G:$G, (MATCH(7, 輔助計算!$E$2:$E$801, 0)+1))="","",INDEX(ERP資料!$G:$G, (MATCH(7, 輔助計算!$E$2:$E$801, 0)+1))), "") | G8: =IFERROR(IF(INDEX(ERP資料!$H:$H, (MATCH(7, 輔助計算!$E$2:$E$801, 0)+1))="","",INDEX(ERP資料!$H:$H, (MATCH(7, 輔助計算!$E$2:$E$801, 0)+1))), "") | H8: =IFERROR(INDEX(輔助計算!$D:$D, (MATCH(7, 輔助計算!$E$2:$E$801, 0)+1)), "") | I8: =IFERROR(IF(INDEX(ERP資料!$O:$O, (MATCH(7, 輔助計算!$E$2:$E$801, 0)+1))="","",INDEX(ERP資料!$O:$O, (MATCH(7, 輔助計算!$E$2:$E$801, 0)+1))), "") | J8: =IFERROR(IF(INDEX(輔助計算!$D:$D,(MATCH(7, 輔助計算!$E$2:$E$801, 0)+1))="","",INDEX(輔助計算!$D:$D,(MATCH(7, 輔助計算!$E$2:$E$801, 0)+1))*INDEX(ERP資料!$O:$O,(MATCH(7, 輔助計算!$E$2:$E$801, 0)+1))), "")
A9: =IFERROR(IF(INDEX(ERP資料!$B:$B, (MATCH(8, 輔助計算!$E$2:$E$801, 0)+1))="","",INDEX(ERP資料!$B:$B, (MATCH(8, 輔助計算!$E$2:$E$801, 0)+1))), "") | B9: =IFERROR(IF(INDEX(ERP資料!$A:$A, (MATCH(8, 輔助計算!$E$2:$E$801, 0)+1))="","",INDEX(ERP資料!$A:$A, (MATCH(8, 輔助計算!$E$2:$E$801, 0)+1))), "") | C9: =IFERROR(IF(INDEX(ERP資料!$S:$S, (MATCH(8, 輔助計算!$E$2:$E$801, 0)+1))="","",INDEX(ERP資料!$S:$S, (MATCH(8, 輔助計算!$E$2:$E$801, 0)+1))), "") | D9: =IFERROR(IF(INDEX(ERP資料!$E:$E, (MATCH(8, 輔助計算!$E$2:$E$801, 0)+1))="","",TRIM(INDEX(ERP資料!$E:$E, (MATCH(8, 輔助計算!$E$2:$E$801, 0)+1)))), "") | E9: =IFERROR(IF(INDEX(ERP資料!$F:$F, (MATCH(8, 輔助計算!$E$2:$E$801, 0)+1))="","",INDEX(ERP資料!$F:$F, (MATCH(8, 輔助計算!$E$2:$E$801, 0)+1))), "") | F9: =IFERROR(IF(INDEX(ERP資料!$G:$G, (MATCH(8, 輔助計算!$E$2:$E$801, 0)+1))="","",INDEX(ERP資料!$G:$G, (MATCH(8, 輔助計算!$E$2:$E$801, 0)+1))), "") | G9: =IFERROR(IF(INDEX(ERP資料!$H:$H, (MATCH(8, 輔助計算!$E$2:$E$801, 0)+1))="","",INDEX(ERP資料!$H:$H, (MATCH(8, 輔助計算!$E$2:$E$801, 0)+1))), "") | H9: =IFERROR(INDEX(輔助計算!$D:$D, (MATCH(8, 輔助計算!$E$2:$E$801, 0)+1)), "") | I9: =IFERROR(IF(INDEX(ERP資料!$O:$O, (MATCH(8, 輔助計算!$E$2:$E$801, 0)+1))="","",INDEX(ERP資料!$O:$O, (MATCH(8, 輔助計算!$E$2:$E$801, 0)+1))), "") | J9: =IFERROR(IF(INDEX(輔助計算!$D:$D,(MATCH(8, 輔助計算!$E$2:$E$801, 0)+1))="","",INDEX(輔助計算!$D:$D,(MATCH(8, 輔助計算!$E$2:$E$801, 0)+1))*INDEX(ERP資料!$O:$O,(MATCH(8, 輔助計算!$E$2:$E$801, 0)+1))), "")
A10: =IFERROR(IF(INDEX(ERP資料!$B:$B, (MATCH(9, 輔助計算!$E$2:$E$801, 0)+1))="","",INDEX(ERP資料!$B:$B, (MATCH(9, 輔助計算!$E$2:$E$801, 0)+1))), "") | B10: =IFERROR(IF(INDEX(ERP資料!$A:$A, (MATCH(9, 輔助計算!$E$2:$E$801, 0)+1))="","",INDEX(ERP資料!$A:$A, (MATCH(9, 輔助計算!$E$2:$E$801, 0)+1))), "") | C10: =IFERROR(IF(INDEX(ERP資料!$S:$S, (MATCH(9, 輔助計算!$E$2:$E$801, 0)+1))="","",INDEX(ERP資料!$S:$S, (MATCH(9, 輔助計算!$E$2:$E$801, 0)+1))), "") | D10: =IFERROR(IF(INDEX(ERP資料!$E:$E, (MATCH(9, 輔助計算!$E$2:$E$801, 0)+1))="","",TRIM(INDEX(ERP資料!$E:$E, (MATCH(9, 輔助計算!$E$2:$E$801, 0)+1)))), "") | E10: =IFERROR(IF(INDEX(ERP資料!$F:$F, (MATCH(9, 輔助計算!$E$2:$E$801, 0)+1))="","",INDEX(ERP資料!$F:$F, (MATCH(9, 輔助計算!$E$2:$E$801, 0)+1))), "") | F10: =IFERROR(IF(INDEX(ERP資料!$G:$G, (MATCH(9, 輔助計算!$E$2:$E$801, 0)+1))="","",INDEX(ERP資料!$G:$G, (MATCH(9, 輔助計算!$E$2:$E$801, 0)+1))), "") | G10: =IFERROR(IF(INDEX(ERP資料!$H:$H, (MATCH(9, 輔助計算!$E$2:$E$801, 0)+1))="","",INDEX(ERP資料!$H:$H, (MATCH(9, 輔助計算!$E$2:$E$801, 0)+1))), "") | H10: =IFERROR(INDEX(輔助計算!$D:$D, (MATCH(9, 輔助計算!$E$2:$E$801, 0)+1)), "") | I10: =IFERROR(IF(INDEX(ERP資料!$O:$O, (MATCH(9, 輔助計算!$E$2:$E$801, 0)+1))="","",INDEX(ERP資料!$O:$O, (MATCH(9, 輔助計算!$E$2:$E$801, 0)+1))), "") | J10: =IFERROR(IF(INDEX(輔助計算!$D:$D,(MATCH(9, 輔助計算!$E$2:$E$801, 0)+1))="","",INDEX(輔助計算!$D:$D,(MATCH(9, 輔助計算!$E$2:$E$801, 0)+1))*INDEX(ERP資料!$O:$O,(MATCH(9, 輔助計算!$E$2:$E$801, 0)+1))), "")
A11: =IFERROR(IF(INDEX(ERP資料!$B:$B, (MATCH(10, 輔助計算!$E$2:$E$801, 0)+1))="","",INDEX(ERP資料!$B:$B, (MATCH(10, 輔助計算!$E$2:$E$801, 0)+1))), "") | B11: =IFERROR(IF(INDEX(ERP資料!$A:$A, (MATCH(10, 輔助計算!$E$2:$E$801, 0)+1))="","",INDEX(ERP資料!$A:$A, (MATCH(10, 輔助計算!$E$2:$E$801, 0)+1))), "") | C11: =IFERROR(IF(INDEX(ERP資料!$S:$S, (MATCH(10, 輔助計算!$E$2:$E$801, 0)+1))="","",INDEX(ERP資料!$S:$S, (MATCH(10, 輔助計算!$E$2:$E$801, 0)+1))), "") | D11: =IFERROR(IF(INDEX(ERP資料!$E:$E, (MATCH(10, 輔助計算!$E$2:$E$801, 0)+1))="","",TRIM(INDEX(ERP資料!$E:$E, (MATCH(10, 輔助計算!$E$2:$E$801, 0)+1)))), "") | E11: =IFERROR(IF(INDEX(ERP資料!$F:$F, (MATCH(10, 輔助計算!$E$2:$E$801, 0)+1))="","",INDEX(ERP資料!$F:$F, (MATCH(10, 輔助計算!$E$2:$E$801, 0)+1))), "") | F11: =IFERROR(IF(INDEX(ERP資料!$G:$G, (MATCH(10, 輔助計算!$E$2:$E$801, 0)+1))="","",INDEX(ERP資料!$G:$G, (MATCH(10, 輔助計算!$E$2:$E$801, 0)+1))), "") | G11: =IFERROR(IF(INDEX(ERP資料!$H:$H, (MATCH(10, 輔助計算!$E$2:$E$801, 0)+1))="","",INDEX(ERP資料!$H:$H, (MATCH(10, 輔助計算!$E$2:$E$801, 0)+1))), "") | H11: =IFERROR(INDEX(輔助計算!$D:$D, (MATCH(10, 輔助計算!$E$2:$E$801, 0)+1)), "") | I11: =IFERROR(IF(INDEX(ERP資料!$O:$O, (MATCH(10, 輔助計算!$E$2:$E$801, 0)+1))="","",INDEX(ERP資料!$O:$O, (MATCH(10, 輔助計算!$E$2:$E$801, 0)+1))), "") | J11: =IFERROR(IF(INDEX(輔助計算!$D:$D,(MATCH(10, 輔助計算!$E$2:$E$801, 0)+1))="","",INDEX(輔助計算!$D:$D,(MATCH(10, 輔助計算!$E$2:$E$801, 0)+1))*INDEX(ERP資料!$O:$O,(MATCH(10, 輔助計算!$E$2:$E$801, 0)+1))), "")
A12: =IFERROR(IF(INDEX(ERP資料!$B:$B, (MATCH(11, 輔助計算!$E$2:$E$801, 0)+1))="","",INDEX(ERP資料!$B:$B, (MATCH(11, 輔助計算!$E$2:$E$801, 0)+1))), "") | B12: =IFERROR(IF(INDEX(ERP資料!$A:$A, (MATCH(11, 輔助計算!$E$2:$E$801, 0)+1))="","",INDEX(ERP資料!$A:$A, (MATCH(11, 輔助計算!$E$2:$E$801, 0)+1))), "") | C12: =IFERROR(IF(INDEX(ERP資料!$S:$S, (MATCH(11, 輔助計算!$E$2:$E$801, 0)+1))="","",INDEX(ERP資料!$S:$S, (MATCH(11, 輔助計算!$E$2:$E$801, 0)+1))), "") | D12: =IFERROR(IF(INDEX(ERP資料!$E:$E, (MATCH(11, 輔助計算!$E$2:$E$801, 0)+1))="","",TRIM(INDEX(ERP資料!$E:$E, (MATCH(11, 輔助計算!$E$2:$E$801, 0)+1)))), "") | E12: =IFERROR(IF(INDEX(ERP資料!$F:$F, (MATCH(11, 輔助計算!$E$2:$E$801, 0)+1))="","",INDEX(ERP資料!$F:$F, (MATCH(11, 輔助計算!$E$2:$E$801, 0)+1))), "") | F12: =IFERROR(IF(INDEX(ERP資料!$G:$G, (MATCH(11, 輔助計算!$E$2:$E$801, 0)+1))="","",INDEX(ERP資料!$G:$G, (MATCH(11, 輔助計算!$E$2:$E$801, 0)+1))), "") | G12: =IFERROR(IF(INDEX(ERP資料!$H:$H, (MATCH(11, 輔助計算!$E$2:$E$801, 0)+1))="","",INDEX(ERP資料!$H:$H, (MATCH(11, 輔助計算!$E$2:$E$801, 0)+1))), "") | H12: =IFERROR(INDEX(輔助計算!$D:$D, (MATCH(11, 輔助計算!$E$2:$E$801, 0)+1)), "") | I12: =IFERROR(IF(INDEX(ERP資料!$O:$O, (MATCH(11, 輔助計算!$E$2:$E$801, 0)+1))="","",INDEX(ERP資料!$O:$O, (MATCH(11, 輔助計算!$E$2:$E$801, 0)+1))), "") | J12: =IFERROR(IF(INDEX(輔助計算!$D:$D,(MATCH(11, 輔助計算!$E$2:$E$801, 0)+1))="","",INDEX(輔助計算!$D:$D,(MATCH(11, 輔助計算!$E$2:$E$801, 0)+1))*INDEX(ERP資料!$O:$O,(MATCH(11, 輔助計算!$E$2:$E$801, 0)+1))), "")
A13: =IFERROR(IF(INDEX(ERP資料!$B:$B, (MATCH(12, 輔助計算!$E$2:$E$801, 0)+1))="","",INDEX(ERP資料!$B:$B, (MATCH(12, 輔助計算!$E$2:$E$801, 0)+1))), "") | B13: =IFERROR(IF(INDEX(ERP資料!$A:$A, (MATCH(12, 輔助計算!$E$2:$E$801, 0)+1))="","",INDEX(ERP資料!$A:$A, (MATCH(12, 輔助計算!$E$2:$E$801, 0)+1))), "") | C13: =IFERROR(IF(INDEX(ERP資料!$S:$S, (MATCH(12, 輔助計算!$E$2:$E$801, 0)+1))="","",INDEX(ERP資料!$S:$S, (MATCH(12, 輔助計算!$E$2:$E$801, 0)+1))), "") | D13: =IFERROR(IF(INDEX(ERP資料!$E:$E, (MATCH(12, 輔助計算!$E$2:$E$801, 0)+1))="","",TRIM(INDEX(ERP資料!$E:$E, (MATCH(12, 輔助計算!$E$2:$E$801, 0)+1)))), "") | E13: =IFERROR(IF(INDEX(ERP資料!$F:$F, (MATCH(12, 輔助計算!$E$2:$E$801, 0)+1))="","",INDEX(ERP資料!$F:$F, (MATCH(12, 輔助計算!$E$2:$E$801, 0)+1))), "") | F13: =IFERROR(IF(INDEX(ERP資料!$G:$G, (MATCH(12, 輔助計算!$E$2:$E$801, 0)+1))="","",INDEX(ERP資料!$G:$G, (MATCH(12, 輔助計算!$E$2:$E$801, 0)+1))), "") | G13: =IFERROR(IF(INDEX(ERP資料!$H:$H, (MATCH(12, 輔助計算!$E$2:$E$801, 0)+1))="","",INDEX(ERP資料!$H:$H, (MATCH(12, 輔助計算!$E$2:$E$801, 0)+1))), "") | H13: =IFERROR(INDEX(輔助計算!$D:$D, (MATCH(12, 輔助計算!$E$2:$E$801, 0)+1)), "") | I13: =IFERROR(IF(INDEX(ERP資料!$O:$O, (MATCH(12, 輔助計算!$E$2:$E$801, 0)+1))="","",INDEX(ERP資料!$O:$O, (MATCH(12, 輔助計算!$E$2:$E$801, 0)+1))), "") | J13: =IFERROR(IF(INDEX(輔助計算!$D:$D,(MATCH(12, 輔助計算!$E$2:$E$801, 0)+1))="","",INDEX(輔助計算!$D:$D,(MATCH(12, 輔助計算!$E$2:$E$801, 0)+1))*INDEX(ERP資料!$O:$O,(MATCH(12, 輔助計算!$E$2:$E$801, 0)+1))), "")
A14: =IFERROR(IF(INDEX(ERP資料!$B:$B, (MATCH(13, 輔助計算!$E$2:$E$801, 0)+1))="","",INDEX(ERP資料!$B:$B, (MATCH(13, 輔助計算!$E$2:$E$801, 0)+1))), "") | B14: =IFERROR(IF(INDEX(ERP資料!$A:$A, (MATCH(13, 輔助計算!$E$2:$E$801, 0)+1))="","",INDEX(ERP資料!$A:$A, (MATCH(13, 輔助計算!$E$2:$E$801, 0)+1))), "") | C14: =IFERROR(IF(INDEX(ERP資料!$S:$S, (MATCH(13, 輔助計算!$E$2:$E$801, 0)+1))="","",INDEX(ERP資料!$S:$S, (MATCH(13, 輔助計算!$E$2:$E$801, 0)+1))), "") | D14: =IFERROR(IF(INDEX(ERP資料!$E:$E, (MATCH(13, 輔助計算!$E$2:$E$801, 0)+1))="","",TRIM(INDEX(ERP資料!$E:$E, (MATCH(13, 輔助計算!$E$2:$E$801, 0)+1)))), "") | E14: =IFERROR(IF(INDEX(ERP資料!$F:$F, (MATCH(13, 輔助計算!$E$2:$E$801, 0)+1))="","",INDEX(ERP資料!$F:$F, (MATCH(13, 輔助計算!$E$2:$E$801, 0)+1))), "") | F14: =IFERROR(IF(INDEX(ERP資料!$G:$G, (MATCH(13, 輔助計算!$E$2:$E$801, 0)+1))="","",INDEX(ERP資料!$G:$G, (MATCH(13, 輔助計算!$E$2:$E$801, 0)+1))), "") | G14: =IFERROR(IF(INDEX(ERP資料!$H:$H, (MATCH(13, 輔助計算!$E$2:$E$801, 0)+1))="","",INDEX(ERP資料!$H:$H, (MATCH(13, 輔助計算!$E$2:$E$801, 0)+1))), "") | H14: =IFERROR(INDEX(輔助計算!$D:$D, (MATCH(13, 輔助計算!$E$2:$E$801, 0)+1)), "") | I14: =IFERROR(IF(INDEX(ERP資料!$O:$O, (MATCH(13, 輔助計算!$E$2:$E$801, 0)+1))="","",INDEX(ERP資料!$O:$O, (MATCH(13, 輔助計算!$E$2:$E$801, 0)+1))), "") | J14: =IFERROR(IF(INDEX(輔助計算!$D:$D,(MATCH(13, 輔助計算!$E$2:$E$801, 0)+1))="","",INDEX(輔助計算!$D:$D,(MATCH(13, 輔助計算!$E$2:$E$801, 0)+1))*INDEX(ERP資料!$O:$O,(MATCH(13, 輔助計算!$E$2:$E$801, 0)+1))), "")
A15: =IFERROR(IF(INDEX(ERP資料!$B:$B, (MATCH(14, 輔助計算!$E$2:$E$801, 0)+1))="","",INDEX(ERP資料!$B:$B, (MATCH(14, 輔助計算!$E$2:$E$801, 0)+1))), "") | B15: =IFERROR(IF(INDEX(ERP資料!$A:$A, (MATCH(14, 輔助計算!$E$2:$E$801, 0)+1))="","",INDEX(ERP資料!$A:$A, (MATCH(14, 輔助計算!$E$2:$E$801, 0)+1))), "") | C15: =IFERROR(IF(INDEX(ERP資料!$S:$S, (MATCH(14, 輔助計算!$E$2:$E$801, 0)+1))="","",INDEX(ERP資料!$S:$S, (MATCH(14, 輔助計算!$E$2:$E$801, 0)+1))), "") | D15: =IFERROR(IF(INDEX(ERP資料!$E:$E, (MATCH(14, 輔助計算!$E$2:$E$801, 0)+1))="","",TRIM(INDEX(ERP資料!$E:$E, (MATCH(14, 輔助計算!$E$2:$E$801, 0)+1)))), "") | E15: =IFERROR(IF(INDEX(ERP資料!$F:$F, (MATCH(14, 輔助計算!$E$2:$E$801, 0)+1))="","",INDEX(ERP資料!$F:$F, (MATCH(14, 輔助計算!$E$2:$E$801, 0)+1))), "") | F15: =IFERROR(IF(INDEX(ERP資料!$G:$G, (MATCH(14, 輔助計算!$E$2:$E$801, 0)+1))="","",INDEX(ERP資料!$G:$G, (MATCH(14, 輔助計算!$E$2:$E$801, 0)+1))), "") | G15: =IFERROR(IF(INDEX(ERP資料!$H:$H, (MATCH(14, 輔助計算!$E$2:$E$801, 0)+1))="","",INDEX(ERP資料!$H:$H, (MATCH(14, 輔助計算!$E$2:$E$801, 0)+1))), "") | H15: =IFERROR(INDEX(輔助計算!$D:$D, (MATCH(14, 輔助計算!$E$2:$E$801, 0)+1)), "") | I15: =IFERROR(IF(INDEX(ERP資料!$O:$O, (MATCH(14, 輔助計算!$E$2:$E$801, 0)+1))="","",INDEX(ERP資料!$O:$O, (MATCH(14, 輔助計算!$E$2:$E$801, 0)+1))), "") | J15: =IFERROR(IF(INDEX(輔助計算!$D:$D,(MATCH(14, 輔助計算!$E$2:$E$801, 0)+1))="","",INDEX(輔助計算!$D:$D,(MATCH(14, 輔助計算!$E$2:$E$801, 0)+1))*INDEX(ERP資料!$O:$O,(MATCH(14, 輔助計算!$E$2:$E$801, 0)+1))), "")
A16: =IFERROR(IF(INDEX(ERP資料!$B:$B, (MATCH(15, 輔助計算!$E$2:$E$801, 0)+1))="","",INDEX(ERP資料!$B:$B, (MATCH(15, 輔助計算!$E$2:$E$801, 0)+1))), "") | B16: =IFERROR(IF(INDEX(ERP資料!$A:$A, (MATCH(15, 輔助計算!$E$2:$E$801, 0)+1))="","",INDEX(ERP資料!$A:$A, (MATCH(15, 輔助計算!$E$2:$E$801, 0)+1))), "") | C16: =IFERROR(IF(INDEX(ERP資料!$S:$S, (MATCH(15, 輔助計算!$E$2:$E$801, 0)+1))="","",INDEX(ERP資料!$S:$S, (MATCH(15, 輔助計算!$E$2:$E$801, 0)+1))), "") | D16: =IFERROR(IF(INDEX(ERP資料!$E:$E, (MATCH(15, 輔助計算!$E$2:$E$801, 0)+1))="","",TRIM(INDEX(ERP資料!$E:$E, (MATCH(15, 輔助計算!$E$2:$E$801, 0)+1)))), "") | E16: =IFERROR(IF(INDEX(ERP資料!$F:$F, (MATCH(15, 輔助計算!$E$2:$E$801, 0)+1))="","",INDEX(ERP資料!$F:$F, (MATCH(15, 輔助計算!$E$2:$E$801, 0)+1))), "") | F16: =IFERROR(IF(INDEX(ERP資料!$G:$G, (MATCH(15, 輔助計算!$E$2:$E$801, 0)+1))="","",INDEX(ERP資料!$G:$G, (MATCH(15, 輔助計算!$E$2:$E$801, 0)+1))), "") | G16: =IFERROR(IF(INDEX(ERP資料!$H:$H, (MATCH(15, 輔助計算!$E$2:$E$801, 0)+1))="","",INDEX(ERP資料!$H:$H, (MATCH(15, 輔助計算!$E$2:$E$801, 0)+1))), "") | H16: =IFERROR(INDEX(輔助計算!$D:$D, (MATCH(15, 輔助計算!$E$2:$E$801, 0)+1)), "") | I16: =IFERROR(IF(INDEX(ERP資料!$O:$O, (MATCH(15, 輔助計算!$E$2:$E$801, 0)+1))="","",INDEX(ERP資料!$O:$O, (MATCH(15, 輔助計算!$E$2:$E$801, 0)+1))), "") | J16: =IFERROR(IF(INDEX(輔助計算!$D:$D,(MATCH(15, 輔助計算!$E$2:$E$801, 0)+1))="","",INDEX(輔助計算!$D:$D,(MATCH(15, 輔助計算!$E$2:$E$801, 0)+1))*INDEX(ERP資料!$O:$O,(MATCH(15, 輔助計算!$E$2:$E$801, 0)+1))), "")
A17: =IFERROR(IF(INDEX(ERP資料!$B:$B, (MATCH(16, 輔助計算!$E$2:$E$801, 0)+1))="","",INDEX(ERP資料!$B:$B, (MATCH(16, 輔助計算!$E$2:$E$801, 0)+1))), "") | B17: =IFERROR(IF(INDEX(ERP資料!$A:$A, (MATCH(16, 輔助計算!$E$2:$E$801, 0)+1))="","",INDEX(ERP資料!$A:$A, (MATCH(16, 輔助計算!$E$2:$E$801, 0)+1))), "") | C17: =IFERROR(IF(INDEX(ERP資料!$S:$S, (MATCH(16, 輔助計算!$E$2:$E$801, 0)+1))="","",INDEX(ERP資料!$S:$S, (MATCH(16, 輔助計算!$E$2:$E$801, 0)+1))), "") | D17: =IFERROR(IF(INDEX(ERP資料!$E:$E, (MATCH(16, 輔助計算!$E$2:$E$801, 0)+1))="","",TRIM(INDEX(ERP資料!$E:$E, (MATCH(16, 輔助計算!$E$2:$E$801, 0)+1)))), "") | E17: =IFERROR(IF(INDEX(ERP資料!$F:$F, (MATCH(16, 輔助計算!$E$2:$E$801, 0)+1))="","",INDEX(ERP資料!$F:$F, (MATCH(16, 輔助計算!$E$2:$E$801, 0)+1))), "") | F17: =IFERROR(IF(INDEX(ERP資料!$G:$G, (MATCH(16, 輔助計算!$E$2:$E$801, 0)+1))="","",INDEX(ERP資料!$G:$G, (MATCH(16, 輔助計算!$E$2:$E$801, 0)+1))), "") | G17: =IFERROR(IF(INDEX(ERP資料!$H:$H, (MATCH(16, 輔助計算!$E$2:$E$801, 0)+1))="","",INDEX(ERP資料!$H:$H, (MATCH(16, 輔助計算!$E$2:$E$801, 0)+1))), "") | H17: =IFERROR(INDEX(輔助計算!$D:$D, (MATCH(16, 輔助計算!$E$2:$E$801, 0)+1)), "") | I17: =IFERROR(IF(INDEX(ERP資料!$O:$O, (MATCH(16, 輔助計算!$E$2:$E$801, 0)+1))="","",INDEX(ERP資料!$O:$O, (MATCH(16, 輔助計算!$E$2:$E$801, 0)+1))), "") | J17: =IFERROR(IF(INDEX(輔助計算!$D:$D,(MATCH(16, 輔助計算!$E$2:$E$801, 0)+1))="","",INDEX(輔助計算!$D:$D,(MATCH(16, 輔助計算!$E$2:$E$801, 0)+1))*INDEX(ERP資料!$O:$O,(MATCH(16, 輔助計算!$E$2:$E$801, 0)+1))), "")
A18: =IFERROR(IF(INDEX(ERP資料!$B:$B, (MATCH(17, 輔助計算!$E$2:$E$801, 0)+1))="","",INDEX(ERP資料!$B:$B, (MATCH(17, 輔助計算!$E$2:$E$801, 0)+1))), "") | B18: =IFERROR(IF(INDEX(ERP資料!$A:$A, (MATCH(17, 輔助計算!$E$2:$E$801, 0)+1))="","",INDEX(ERP資料!$A:$A, (MATCH(17, 輔助計算!$E$2:$E$801, 0)+1))), "") | C18: =IFERROR(IF(INDEX(ERP資料!$S:$S, (MATCH(17, 輔助計算!$E$2:$E$801, 0)+1))="","",INDEX(ERP資料!$S:$S, (MATCH(17, 輔助計算!$E$2:$E$801, 0)+1))), "") | D18: =IFERROR(IF(INDEX(ERP資料!$E:$E, (MATCH(17, 輔助計算!$E$2:$E$801, 0)+1))="","",TRIM(INDEX(ERP資料!$E:$E, (MATCH(17, 輔助計算!$E$2:$E$801, 0)+1)))), "") | E18: =IFERROR(IF(INDEX(ERP資料!$F:$F, (MATCH(17, 輔助計算!$E$2:$E$801, 0)+1))="","",INDEX(ERP資料!$F:$F, (MATCH(17, 輔助計算!$E$2:$E$801, 0)+1))), "") | F18: =IFERROR(IF(INDEX(ERP資料!$G:$G, (MATCH(17, 輔助計算!$E$2:$E$801, 0)+1))="","",INDEX(ERP資料!$G:$G, (MATCH(17, 輔助計算!$E$2:$E$801, 0)+1))), "") | G18: =IFERROR(IF(INDEX(ERP資料!$H:$H, (MATCH(17, 輔助計算!$E$2:$E$801, 0)+1))="","",INDEX(ERP資料!$H:$H, (MATCH(17, 輔助計算!$E$2:$E$801, 0)+1))), "") | H18: =IFERROR(INDEX(輔助計算!$D:$D, (MATCH(17, 輔助計算!$E$2:$E$801, 0)+1)), "") | I18: =IFERROR(IF(INDEX(ERP資料!$O:$O, (MATCH(17, 輔助計算!$E$2:$E$801, 0)+1))="","",INDEX(ERP資料!$O:$O, (MATCH(17, 輔助計算!$E$2:$E$801, 0)+1))), "") | J18: =IFERROR(IF(INDEX(輔助計算!$D:$D,(MATCH(17, 輔助計算!$E$2:$E$801, 0)+1))="","",INDEX(輔助計算!$D:$D,(MATCH(17, 輔助計算!$E$2:$E$801, 0)+1))*INDEX(ERP資料!$O:$O,(MATCH(17, 輔助計算!$E$2:$E$801, 0)+1))), "")
A19: =IFERROR(IF(INDEX(ERP資料!$B:$B, (MATCH(18, 輔助計算!$E$2:$E$801, 0)+1))="","",INDEX(ERP資料!$B:$B, (MATCH(18, 輔助計算!$E$2:$E$801, 0)+1))), "") | B19: =IFERROR(IF(INDEX(ERP資料!$A:$A, (MATCH(18, 輔助計算!$E$2:$E$801, 0)+1))="","",INDEX(ERP資料!$A:$A, (MATCH(18, 輔助計算!$E$2:$E$801, 0)+1))), "") | C19: =IFERROR(IF(INDEX(ERP資料!$S:$S, (MATCH(18, 輔助計算!$E$2:$E$801, 0)+1))="","",INDEX(ERP資料!$S:$S, (MATCH(18, 輔助計算!$E$2:$E$801, 0)+1))), "") | D19: =IFERROR(IF(INDEX(ERP資料!$E:$E, (MATCH(18, 輔助計算!$E$2:$E$801, 0)+1))="","",TRIM(INDEX(ERP資料!$E:$E, (MATCH(18, 輔助計算!$E$2:$E$801, 0)+1)))), "") | E19: =IFERROR(IF(INDEX(ERP資料!$F:$F, (MATCH(18, 輔助計算!$E$2:$E$801, 0)+1))="","",INDEX(ERP資料!$F:$F, (MATCH(18, 輔助計算!$E$2:$E$801, 0)+1))), "") | F19: =IFERROR(IF(INDEX(ERP資料!$G:$G, (MATCH(18, 輔助計算!$E$2:$E$801, 0)+1))="","",INDEX(ERP資料!$G:$G, (MATCH(18, 輔助計算!$E$2:$E$801, 0)+1))), "") | G19: =IFERROR(IF(INDEX(ERP資料!$H:$H, (MATCH(18, 輔助計算!$E$2:$E$801, 0)+1))="","",INDEX(ERP資料!$H:$H, (MATCH(18, 輔助計算!$E$2:$E$801, 0)+1))), "") | H19: =IFERROR(INDEX(輔助計算!$D:$D, (MATCH(18, 輔助計算!$E$2:$E$801, 0)+1)), "") | I19: =IFERROR(IF(INDEX(ERP資料!$O:$O, (MATCH(18, 輔助計算!$E$2:$E$801, 0)+1))="","",INDEX(ERP資料!$O:$O, (MATCH(18, 輔助計算!$E$2:$E$801, 0)+1))), "") | J19: =IFERROR(IF(INDEX(輔助計算!$D:$D,(MATCH(18, 輔助計算!$E$2:$E$801, 0)+1))="","",INDEX(輔助計算!$D:$D,(MATCH(18, 輔助計算!$E$2:$E$801, 0)+1))*INDEX(ERP資料!$O:$O,(MATCH(18, 輔助計算!$E$2:$E$801, 0)+1))), "")
A20: =IFERROR(IF(INDEX(ERP資料!$B:$B, (MATCH(19, 輔助計算!$E$2:$E$801, 0)+1))="","",INDEX(ERP資料!$B:$B, (MATCH(19, 輔助計算!$E$2:$E$801, 0)+1))), "") | B20: =IFERROR(IF(INDEX(ERP資料!$A:$A, (MATCH(19, 輔助計算!$E$2:$E$801, 0)+1))="","",INDEX(ERP資料!$A:$A, (MATCH(19, 輔助計算!$E$2:$E$801, 0)+1))), "") | C20: =IFERROR(IF(INDEX(ERP資料!$S:$S, (MATCH(19, 輔助計算!$E$2:$E$801, 0)+1))="","",INDEX(ERP資料!$S:$S, (MATCH(19, 輔助計算!$E$2:$E$801, 0)+1))), "") | D20: =IFERROR(IF(INDEX(ERP資料!$E:$E, (MATCH(19, 輔助計算!$E$2:$E$801, 0)+1))="","",TRIM(INDEX(ERP資料!$E:$E, (MATCH(19, 輔助計算!$E$2:$E$801, 0)+1)))), "") | E20: =IFERROR(IF(INDEX(ERP資料!$F:$F, (MATCH(19, 輔助計算!$E$2:$E$801, 0)+1))="","",INDEX(ERP資料!$F:$F, (MATCH(19, 輔助計算!$E$2:$E$801, 0)+1))), "") | F20: =IFERROR(IF(INDEX(ERP資料!$G:$G, (MATCH(19, 輔助計算!$E$2:$E$801, 0)+1))="","",INDEX(ERP資料!$G:$G, (MATCH(19, 輔助計算!$E$2:$E$801, 0)+1))), "") | G20: =IFERROR(IF(INDEX(ERP資料!$H:$H, (MATCH(19, 輔助計算!$E$2:$E$801, 0)+1))="","",INDEX(ERP資料!$H:$H, (MATCH(19, 輔助計算!$E$2:$E$801, 0)+1))), "") | H20: =IFERROR(INDEX(輔助計算!$D:$D, (MATCH(19, 輔助計算!$E$2:$E$801, 0)+1)), "") | I20: =IFERROR(IF(INDEX(ERP資料!$O:$O, (MATCH(19, 輔助計算!$E$2:$E$801, 0)+1))="","",INDEX(ERP資料!$O:$O, (MATCH(19, 輔助計算!$E$2:$E$801, 0)+1))), "") | J20: =IFERROR(IF(INDEX(輔助計算!$D:$D,(MATCH(19, 輔助計算!$E$2:$E$801, 0)+1))="","",INDEX(輔助計算!$D:$D,(MATCH(19, 輔助計算!$E$2:$E$801, 0)+1))*INDEX(ERP資料!$O:$O,(MATCH(19, 輔助計算!$E$2:$E$801, 0)+1))), "")
A21: =IFERROR(IF(INDEX(ERP資料!$B:$B, (MATCH(20, 輔助計算!$E$2:$E$801, 0)+1))="","",INDEX(ERP資料!$B:$B, (MATCH(20, 輔助計算!$E$2:$E$801, 0)+1))), "") | B21: =IFERROR(IF(INDEX(ERP資料!$A:$A, (MATCH(20, 輔助計算!$E$2:$E$801, 0)+1))="","",INDEX(ERP資料!$A:$A, (MATCH(20, 輔助計算!$E$2:$E$801, 0)+1))), "") | C21: =IFERROR(IF(INDEX(ERP資料!$S:$S, (MATCH(20, 輔助計算!$E$2:$E$801, 0)+1))="","",INDEX(ERP資料!$S:$S, (MATCH(20, 輔助計算!$E$2:$E$801, 0)+1))), "") | D21: =IFERROR(IF(INDEX(ERP資料!$E:$E, (MATCH(20, 輔助計算!$E$2:$E$801, 0)+1))="","",TRIM(INDEX(ERP資料!$E:$E, (MATCH(20, 輔助計算!$E$2:$E$801, 0)+1)))), "") | E21: =IFERROR(IF(INDEX(ERP資料!$F:$F, (MATCH(20, 輔助計算!$E$2:$E$801, 0)+1))="","",INDEX(ERP資料!$F:$F, (MATCH(20, 輔助計算!$E$2:$E$801, 0)+1))), "") | F21: =IFERROR(IF(INDEX(ERP資料!$G:$G, (MATCH(20, 輔助計算!$E$2:$E$801, 0)+1))="","",INDEX(ERP資料!$G:$G, (MATCH(20, 輔助計算!$E$2:$E$801, 0)+1))), "") | G21: =IFERROR(IF(INDEX(ERP資料!$H:$H, (MATCH(20, 輔助計算!$E$2:$E$801, 0)+1))="","",INDEX(ERP資料!$H:$H, (MATCH(20, 輔助計算!$E$2:$E$801, 0)+1))), "") | H21: =IFERROR(INDEX(輔助計算!$D:$D, (MATCH(20, 輔助計算!$E$2:$E$801, 0)+1)), "") | I21: =IFERROR(IF(INDEX(ERP資料!$O:$O, (MATCH(20, 輔助計算!$E$2:$E$801, 0)+1))="","",INDEX(ERP資料!$O:$O, (MATCH(20, 輔助計算!$E$2:$E$801, 0)+1))), "") | J21: =IFERROR(IF(INDEX(輔助計算!$D:$D,(MATCH(20, 輔助計算!$E$2:$E$801, 0)+1))="","",INDEX(輔助計算!$D:$D,(MATCH(20, 輔助計算!$E$2:$E$801, 0)+1))*INDEX(ERP資料!$O:$O,(MATCH(20, 輔助計算!$E$2:$E$801, 0)+1))), "")
A22: =IFERROR(IF(INDEX(ERP資料!$B:$B, (MATCH(21, 輔助計算!$E$2:$E$801, 0)+1))="","",INDEX(ERP資料!$B:$B, (MATCH(21, 輔助計算!$E$2:$E$801, 0)+1))), "") | B22: =IFERROR(IF(INDEX(ERP資料!$A:$A, (MATCH(21, 輔助計算!$E$2:$E$801, 0)+1))="","",INDEX(ERP資料!$A:$A, (MATCH(21, 輔助計算!$E$2:$E$801, 0)+1))), "") | C22: =IFERROR(IF(INDEX(ERP資料!$S:$S, (MATCH(21, 輔助計算!$E$2:$E$801, 0)+1))="","",INDEX(ERP資料!$S:$S, (MATCH(21, 輔助計算!$E$2:$E$801, 0)+1))), "") | D22: =IFERROR(IF(INDEX(ERP資料!$E:$E, (MATCH(21, 輔助計算!$E$2:$E$801, 0)+1))="","",TRIM(INDEX(ERP資料!$E:$E, (MATCH(21, 輔助計算!$E$2:$E$801, 0)+1)))), "") | E22: =IFERROR(IF(INDEX(ERP資料!$F:$F, (MATCH(21, 輔助計算!$E$2:$E$801, 0)+1))="","",INDEX(ERP資料!$F:$F, (MATCH(21, 輔助計算!$E$2:$E$801, 0)+1))), "") | F22: =IFERROR(IF(INDEX(ERP資料!$G:$G, (MATCH(21, 輔助計算!$E$2:$E$801, 0)+1))="","",INDEX(ERP資料!$G:$G, (MATCH(21, 輔助計算!$E$2:$E$801, 0)+1))), "") | G22: =IFERROR(IF(INDEX(ERP資料!$H:$H, (MATCH(21, 輔助計算!$E$2:$E$801, 0)+1))="","",INDEX(ERP資料!$H:$H, (MATCH(21, 輔助計算!$E$2:$E$801, 0)+1))), "") | H22: =IFERROR(INDEX(輔助計算!$D:$D, (MATCH(21, 輔助計算!$E$2:$E$801, 0)+1)), "") | I22: =IFERROR(IF(INDEX(ERP資料!$O:$O, (MATCH(21, 輔助計算!$E$2:$E$801, 0)+1))="","",INDEX(ERP資料!$O:$O, (MATCH(21, 輔助計算!$E$2:$E$801, 0)+1))), "") | J22: =IFERROR(IF(INDEX(輔助計算!$D:$D,(MATCH(21, 輔助計算!$E$2:$E$801, 0)+1))="","",INDEX(輔助計算!$D:$D,(MATCH(21, 輔助計算!$E$2:$E$801, 0)+1))*INDEX(ERP資料!$O:$O,(MATCH(21, 輔助計算!$E$2:$E$801, 0)+1))), "")
A23: =IFERROR(IF(INDEX(ERP資料!$B:$B, (MATCH(22, 輔助計算!$E$2:$E$801, 0)+1))="","",INDEX(ERP資料!$B:$B, (MATCH(22, 輔助計算!$E$2:$E$801, 0)+1))), "") | B23: =IFERROR(IF(INDEX(ERP資料!$A:$A, (MATCH(22, 輔助計算!$E$2:$E$801, 0)+1))="","",INDEX(ERP資料!$A:$A, (MATCH(22, 輔助計算!$E$2:$E$801, 0)+1))), "") | C23: =IFERROR(IF(INDEX(ERP資料!$S:$S, (MATCH(22, 輔助計算!$E$2:$E$801, 0)+1))="","",INDEX(ERP資料!$S:$S, (MATCH(22, 輔助計算!$E$2:$E$801, 0)+1))), "") | D23: =IFERROR(IF(INDEX(ERP資料!$E:$E, (MATCH(22, 輔助計算!$E$2:$E$801, 0)+1))="","",TRIM(INDEX(ERP資料!$E:$E, (MATCH(22, 輔助計算!$E$2:$E$801, 0)+1)))), "") | E23: =IFERROR(IF(INDEX(ERP資料!$F:$F, (MATCH(22, 輔助計算!$E$2:$E$801, 0)+1))="","",INDEX(ERP資料!$F:$F, (MATCH(22, 輔助計算!$E$2:$E$801, 0)+1))), "") | F23: =IFERROR(IF(INDEX(ERP資料!$G:$G, (MATCH(22, 輔助計算!$E$2:$E$801, 0)+1))="","",INDEX(ERP資料!$G:$G, (MATCH(22, 輔助計算!$E$2:$E$801, 0)+1))), "") | G23: =IFERROR(IF(INDEX(ERP資料!$H:$H, (MATCH(22, 輔助計算!$E$2:$E$801, 0)+1))="","",INDEX(ERP資料!$H:$H, (MATCH(22, 輔助計算!$E$2:$E$801, 0)+1))), "") | H23: =IFERROR(INDEX(輔助計算!$D:$D, (MATCH(22, 輔助計算!$E$2:$E$801, 0)+1)), "") | I23: =IFERROR(IF(INDEX(ERP資料!$O:$O, (MATCH(22, 輔助計算!$E$2:$E$801, 0)+1))="","",INDEX(ERP資料!$O:$O, (MATCH(22, 輔助計算!$E$2:$E$801, 0)+1))), "") | J23: =IFERROR(IF(INDEX(輔助計算!$D:$D,(MATCH(22, 輔助計算!$E$2:$E$801, 0)+1))="","",INDEX(輔助計算!$D:$D,(MATCH(22, 輔助計算!$E$2:$E$801, 0)+1))*INDEX(ERP資料!$O:$O,(MATCH(22, 輔助計算!$E$2:$E$801, 0)+1))), "")
A24: =IFERROR(IF(INDEX(ERP資料!$B:$B, (MATCH(23, 輔助計算!$E$2:$E$801, 0)+1))="","",INDEX(ERP資料!$B:$B, (MATCH(23, 輔助計算!$E$2:$E$801, 0)+1))), "") | B24: =IFERROR(IF(INDEX(ERP資料!$A:$A, (MATCH(23, 輔助計算!$E$2:$E$801, 0)+1))="","",INDEX(ERP資料!$A:$A, (MATCH(23, 輔助計算!$E$2:$E$801, 0)+1))), "") | C24: =IFERROR(IF(INDEX(ERP資料!$S:$S, (MATCH(23, 輔助計算!$E$2:$E$801, 0)+1))="","",INDEX(ERP資料!$S:$S, (MATCH(23, 輔助計算!$E$2:$E$801, 0)+1))), "") | D24: =IFERROR(IF(INDEX(ERP資料!$E:$E, (MATCH(23, 輔助計算!$E$2:$E$801, 0)+1))="","",TRIM(INDEX(ERP資料!$E:$E, (MATCH(23, 輔助計算!$E$2:$E$801, 0)+1)))), "") | E24: =IFERROR(IF(INDEX(ERP資料!$F:$F, (MATCH(23, 輔助計算!$E$2:$E$801, 0)+1))="","",INDEX(ERP資料!$F:$F, (MATCH(23, 輔助計算!$E$2:$E$801, 0)+1))), "") | F24: =IFERROR(IF(INDEX(ERP資料!$G:$G, (MATCH(23, 輔助計算!$E$2:$E$801, 0)+1))="","",INDEX(ERP資料!$G:$G, (MATCH(23, 輔助計算!$E$2:$E$801, 0)+1))), "") | G24: =IFERROR(IF(INDEX(ERP資料!$H:$H, (MATCH(23, 輔助計算!$E$2:$E$801, 0)+1))="","",INDEX(ERP資料!$H:$H, (MATCH(23, 輔助計算!$E$2:$E$801, 0)+1))), "") | H24: =IFERROR(INDEX(輔助計算!$D:$D, (MATCH(23, 輔助計算!$E$2:$E$801, 0)+1)), "") | I24: =IFERROR(IF(INDEX(ERP資料!$O:$O, (MATCH(23, 輔助計算!$E$2:$E$801, 0)+1))="","",INDEX(ERP資料!$O:$O, (MATCH(23, 輔助計算!$E$2:$E$801, 0)+1))), "") | J24: =IFERROR(IF(INDEX(輔助計算!$D:$D,(MATCH(23, 輔助計算!$E$2:$E$801, 0)+1))="","",INDEX(輔助計算!$D:$D,(MATCH(23, 輔助計算!$E$2:$E$801, 0)+1))*INDEX(ERP資料!$O:$O,(MATCH(23, 輔助計算!$E$2:$E$801, 0)+1))), "")
A25: =IFERROR(IF(INDEX(ERP資料!$B:$B, (MATCH(24, 輔助計算!$E$2:$E$801, 0)+1))="","",INDEX(ERP資料!$B:$B, (MATCH(24, 輔助計算!$E$2:$E$801, 0)+1))), "") | B25: =IFERROR(IF(INDEX(ERP資料!$A:$A, (MATCH(24, 輔助計算!$E$2:$E$801, 0)+1))="","",INDEX(ERP資料!$A:$A, (MATCH(24, 輔助計算!$E$2:$E$801, 0)+1))), "") | C25: =IFERROR(IF(INDEX(ERP資料!$S:$S, (MATCH(24, 輔助計算!$E$2:$E$801, 0)+1))="","",INDEX(ERP資料!$S:$S, (MATCH(24, 輔助計算!$E$2:$E$801, 0)+1))), "") | D25: =IFERROR(IF(INDEX(ERP資料!$E:$E, (MATCH(24, 輔助計算!$E$2:$E$801, 0)+1))="","",TRIM(INDEX(ERP資料!$E:$E, (MATCH(24, 輔助計算!$E$2:$E$801, 0)+1)))), "") | E25: =IFERROR(IF(INDEX(ERP資料!$F:$F, (MATCH(24, 輔助計算!$E$2:$E$801, 0)+1))="","",INDEX(ERP資料!$F:$F, (MATCH(24, 輔助計算!$E$2:$E$801, 0)+1))), "") | F25: =IFERROR(IF(INDEX(ERP資料!$G:$G, (MATCH(24, 輔助計算!$E$2:$E$801, 0)+1))="","",INDEX(ERP資料!$G:$G, (MATCH(24, 輔助計算!$E$2:$E$801, 0)+1))), "") | G25: =IFERROR(IF(INDEX(ERP資料!$H:$H, (MATCH(24, 輔助計算!$E$2:$E$801, 0)+1))="","",INDEX(ERP資料!$H:$H, (MATCH(24, 輔助計算!$E$2:$E$801, 0)+1))), "") | H25: =IFERROR(INDEX(輔助計算!$D:$D, (MATCH(24, 輔助計算!$E$2:$E$801, 0)+1)), "") | I25: =IFERROR(IF(INDEX(ERP資料!$O:$O, (MATCH(24, 輔助計算!$E$2:$E$801, 0)+1))="","",INDEX(ERP資料!$O:$O, (MATCH(24, 輔助計算!$E$2:$E$801, 0)+1))), "") | J25: =IFERROR(IF(INDEX(輔助計算!$D:$D,(MATCH(24, 輔助計算!$E$2:$E$801, 0)+1))="","",INDEX(輔助計算!$D:$D,(MATCH(24, 輔助計算!$E$2:$E$801, 0)+1))*INDEX(ERP資料!$O:$O,(MATCH(24, 輔助計算!$E$2:$E$801, 0)+1))), "")
A26: =IFERROR(IF(INDEX(ERP資料!$B:$B, (MATCH(25, 輔助計算!$E$2:$E$801, 0)+1))="","",INDEX(ERP資料!$B:$B, (MATCH(25, 輔助計算!$E$2:$E$801, 0)+1))), "") | B26: =IFERROR(IF(INDEX(ERP資料!$A:$A, (MATCH(25, 輔助計算!$E$2:$E$801, 0)+1))="","",INDEX(ERP資料!$A:$A, (MATCH(25, 輔助計算!$E$2:$E$801, 0)+1))), "") | C26: =IFERROR(IF(INDEX(ERP資料!$S:$S, (MATCH(25, 輔助計算!$E$2:$E$801, 0)+1))="","",INDEX(ERP資料!$S:$S, (MATCH(25, 輔助計算!$E$2:$E$801, 0)+1))), "") | D26: =IFERROR(IF(INDEX(ERP資料!$E:$E, (MATCH(25, 輔助計算!$E$2:$E$801, 0)+1))="","",TRIM(INDEX(ERP資料!$E:$E, (MATCH(25, 輔助計算!$E$2:$E$801, 0)+1)))), "") | E26: =IFERROR(IF(INDEX(ERP資料!$F:$F, (MATCH(25, 輔助計算!$E$2:$E$801, 0)+1))="","",INDEX(ERP資料!$F:$F, (MATCH(25, 輔助計算!$E$2:$E$801, 0)+1))), "") | F26: =IFERROR(IF(INDEX(ERP資料!$G:$G, (MATCH(25, 輔助計算!$E$2:$E$801, 0)+1))="","",INDEX(ERP資料!$G:$G, (MATCH(25, 輔助計算!$E$2:$E$801, 0)+1))), "") | G26: =IFERROR(IF(INDEX(ERP資料!$H:$H, (MATCH(25, 輔助計算!$E$2:$E$801, 0)+1))="","",INDEX(ERP資料!$H:$H, (MATCH(25, 輔助計算!$E$2:$E$801, 0)+1))), "") | H26: =IFERROR(INDEX(輔助計算!$D:$D, (MATCH(25, 輔助計算!$E$2:$E$801, 0)+1)), "") | I26: =IFERROR(IF(INDEX(ERP資料!$O:$O, (MATCH(25, 輔助計算!$E$2:$E$801, 0)+1))="","",INDEX(ERP資料!$O:$O, (MATCH(25, 輔助計算!$E$2:$E$801, 0)+1))), "") | J26: =IFERROR(IF(INDEX(輔助計算!$D:$D,(MATCH(25, 輔助計算!$E$2:$E$801, 0)+1))="","",INDEX(輔助計算!$D:$D,(MATCH(25, 輔助計算!$E$2:$E$801, 0)+1))*INDEX(ERP資料!$O:$O,(MATCH(25, 輔助計算!$E$2:$E$801, 0)+1))), "")
A27: =IFERROR(IF(INDEX(ERP資料!$B:$B, (MATCH(26, 輔助計算!$E$2:$E$801, 0)+1))="","",INDEX(ERP資料!$B:$B, (MATCH(26, 輔助計算!$E$2:$E$801, 0)+1))), "") | B27: =IFERROR(IF(INDEX(ERP資料!$A:$A, (MATCH(26, 輔助計算!$E$2:$E$801, 0)+1))="","",INDEX(ERP資料!$A:$A, (MATCH(26, 輔助計算!$E$2:$E$801, 0)+1))), "") | C27: =IFERROR(IF(INDEX(ERP資料!$S:$S, (MATCH(26, 輔助計算!$E$2:$E$801, 0)+1))="","",INDEX(ERP資料!$S:$S, (MATCH(26, 輔助計算!$E$2:$E$801, 0)+1))), "") | D27: =IFERROR(IF(INDEX(ERP資料!$E:$E, (MATCH(26, 輔助計算!$E$2:$E$801, 0)+1))="","",TRIM(INDEX(ERP資料!$E:$E, (MATCH(26, 輔助計算!$E$2:$E$801, 0)+1)))), "") | E27: =IFERROR(IF(INDEX(ERP資料!$F:$F, (MATCH(26, 輔助計算!$E$2:$E$801, 0)+1))="","",INDEX(ERP資料!$F:$F, (MATCH(26, 輔助計算!$E$2:$E$801, 0)+1))), "") | F27: =IFERROR(IF(INDEX(ERP資料!$G:$G, (MATCH(26, 輔助計算!$E$2:$E$801, 0)+1))="","",INDEX(ERP資料!$G:$G, (MATCH(26, 輔助計算!$E$2:$E$801, 0)+1))), "") | G27: =IFERROR(IF(INDEX(ERP資料!$H:$H, (MATCH(26, 輔助計算!$E$2:$E$801, 0)+1))="","",INDEX(ERP資料!$H:$H, (MATCH(26, 輔助計算!$E$2:$E$801, 0)+1))), "") | H27: =IFERROR(INDEX(輔助計算!$D:$D, (MATCH(26, 輔助計算!$E$2:$E$801, 0)+1)), "") | I27: =IFERROR(IF(INDEX(ERP資料!$O:$O, (MATCH(26, 輔助計算!$E$2:$E$801, 0)+1))="","",INDEX(ERP資料!$O:$O, (MATCH(26, 輔助計算!$E$2:$E$801, 0)+1))), "") | J27: =IFERROR(IF(INDEX(輔助計算!$D:$D,(MATCH(26, 輔助計算!$E$2:$E$801, 0)+1))="","",INDEX(輔助計算!$D:$D,(MATCH(26, 輔助計算!$E$2:$E$801, 0)+1))*INDEX(ERP資料!$O:$O,(MATCH(26, 輔助計算!$E$2:$E$801, 0)+1))), "")
A28: =IFERROR(IF(INDEX(ERP資料!$B:$B, (MATCH(27, 輔助計算!$E$2:$E$801, 0)+1))="","",INDEX(ERP資料!$B:$B, (MATCH(27, 輔助計算!$E$2:$E$801, 0)+1))), "") | B28: =IFERROR(IF(INDEX(ERP資料!$A:$A, (MATCH(27, 輔助計算!$E$2:$E$801, 0)+1))="","",INDEX(ERP資料!$A:$A, (MATCH(27, 輔助計算!$E$2:$E$801, 0)+1))), "") | C28: =IFERROR(IF(INDEX(ERP資料!$S:$S, (MATCH(27, 輔助計算!$E$2:$E$801, 0)+1))="","",INDEX(ERP資料!$S:$S, (MATCH(27, 輔助計算!$E$2:$E$801, 0)+1))), "") | D28: =IFERROR(IF(INDEX(ERP資料!$E:$E, (MATCH(27, 輔助計算!$E$2:$E$801, 0)+1))="","",TRIM(INDEX(ERP資料!$E:$E, (MATCH(27, 輔助計算!$E$2:$E$801, 0)+1)))), "") | E28: =IFERROR(IF(INDEX(ERP資料!$F:$F, (MATCH(27, 輔助計算!$E$2:$E$801, 0)+1))="","",INDEX(ERP資料!$F:$F, (MATCH(27, 輔助計算!$E$2:$E$801, 0)+1))), "") | F28: =IFERROR(IF(INDEX(ERP資料!$G:$G, (MATCH(27, 輔助計算!$E$2:$E$801, 0)+1))="","",INDEX(ERP資料!$G:$G, (MATCH(27, 輔助計算!$E$2:$E$801, 0)+1))), "") | G28: =IFERROR(IF(INDEX(ERP資料!$H:$H, (MATCH(27, 輔助計算!$E$2:$E$801, 0)+1))="","",INDEX(ERP資料!$H:$H, (MATCH(27, 輔助計算!$E$2:$E$801, 0)+1))), "") | H28: =IFERROR(INDEX(輔助計算!$D:$D, (MATCH(27, 輔助計算!$E$2:$E$801, 0)+1)), "") | I28: =IFERROR(IF(INDEX(ERP資料!$O:$O, (MATCH(27, 輔助計算!$E$2:$E$801, 0)+1))="","",INDEX(ERP資料!$O:$O, (MATCH(27, 輔助計算!$E$2:$E$801, 0)+1))), "") | J28: =IFERROR(IF(INDEX(輔助計算!$D:$D,(MATCH(27, 輔助計算!$E$2:$E$801, 0)+1))="","",INDEX(輔助計算!$D:$D,(MATCH(27, 輔助計算!$E$2:$E$801, 0)+1))*INDEX(ERP資料!$O:$O,(MATCH(27, 輔助計算!$E$2:$E$801, 0)+1))), "")
A29: =IFERROR(IF(INDEX(ERP資料!$B:$B, (MATCH(28, 輔助計算!$E$2:$E$801, 0)+1))="","",INDEX(ERP資料!$B:$B, (MATCH(28, 輔助計算!$E$2:$E$801, 0)+1))), "") | B29: =IFERROR(IF(INDEX(ERP資料!$A:$A, (MATCH(28, 輔助計算!$E$2:$E$801, 0)+1))="","",INDEX(ERP資料!$A:$A, (MATCH(28, 輔助計算!$E$2:$E$801, 0)+1))), "") | C29: =IFERROR(IF(INDEX(ERP資料!$S:$S, (MATCH(28, 輔助計算!$E$2:$E$801, 0)+1))="","",INDEX(ERP資料!$S:$S, (MATCH(28, 輔助計算!$E$2:$E$801, 0)+1))), "") | D29: =IFERROR(IF(INDEX(ERP資料!$E:$E, (MATCH(28, 輔助計算!$E$2:$E$801, 0)+1))="","",TRIM(INDEX(ERP資料!$E:$E, (MATCH(28, 輔助計算!$E$2:$E$801, 0)+1)))), "") | E29: =IFERROR(IF(INDEX(ERP資料!$F:$F, (MATCH(28, 輔助計算!$E$2:$E$801, 0)+1))="","",INDEX(ERP資料!$F:$F, (MATCH(28, 輔助計算!$E$2:$E$801, 0)+1))), "") | F29: =IFERROR(IF(INDEX(ERP資料!$G:$G, (MATCH(28, 輔助計算!$E$2:$E$801, 0)+1))="","",INDEX(ERP資料!$G:$G, (MATCH(28, 輔助計算!$E$2:$E$801, 0)+1))), "") | G29: =IFERROR(IF(INDEX(ERP資料!$H:$H, (MATCH(28, 輔助計算!$E$2:$E$801, 0)+1))="","",INDEX(ERP資料!$H:$H, (MATCH(28, 輔助計算!$E$2:$E$801, 0)+1))), "") | H29: =IFERROR(INDEX(輔助計算!$D:$D, (MATCH(28, 輔助計算!$E$2:$E$801, 0)+1)), "") | I29: =IFERROR(IF(INDEX(ERP資料!$O:$O, (MATCH(28, 輔助計算!$E$2:$E$801, 0)+1))="","",INDEX(ERP資料!$O:$O, (MATCH(28, 輔助計算!$E$2:$E$801, 0)+1))), "") | J29: =IFERROR(IF(INDEX(輔助計算!$D:$D,(MATCH(28, 輔助計算!$E$2:$E$801, 0)+1))="","",INDEX(輔助計算!$D:$D,(MATCH(28, 輔助計算!$E$2:$E$801, 0)+1))*INDEX(ERP資料!$O:$O,(MATCH(28, 輔助計算!$E$2:$E$801, 0)+1))), "")
A30: =IFERROR(IF(INDEX(ERP資料!$B:$B, (MATCH(29, 輔助計算!$E$2:$E$801, 0)+1))="","",INDEX(ERP資料!$B:$B, (MATCH(29, 輔助計算!$E$2:$E$801, 0)+1))), "") | B30: =IFERROR(IF(INDEX(ERP資料!$A:$A, (MATCH(29, 輔助計算!$E$2:$E$801, 0)+1))="","",INDEX(ERP資料!$A:$A, (MATCH(29, 輔助計算!$E$2:$E$801, 0)+1))), "") | C30: =IFERROR(IF(INDEX(ERP資料!$S:$S, (MATCH(29, 輔助計算!$E$2:$E$801, 0)+1))="","",INDEX(ERP資料!$S:$S, (MATCH(29, 輔助計算!$E$2:$E$801, 0)+1))), "") | D30: =IFERROR(IF(INDEX(ERP資料!$E:$E, (MATCH(29, 輔助計算!$E$2:$E$801, 0)+1))="","",TRIM(INDEX(ERP資料!$E:$E, (MATCH(29, 輔助計算!$E$2:$E$801, 0)+1)))), "") | E30: =IFERROR(IF(INDEX(ERP資料!$F:$F, (MATCH(29, 輔助計算!$E$2:$E$801, 0)+1))="","",INDEX(ERP資料!$F:$F, (MATCH(29, 輔助計算!$E$2:$E$801, 0)+1))), "") | F30: =IFERROR(IF(INDEX(ERP資料!$G:$G, (MATCH(29, 輔助計算!$E$2:$E$801, 0)+1))="","",INDEX(ERP資料!$G:$G, (MATCH(29, 輔助計算!$E$2:$E$801, 0)+1))), "") | G30: =IFERROR(IF(INDEX(ERP資料!$H:$H, (MATCH(29, 輔助計算!$E$2:$E$801, 0)+1))="","",INDEX(ERP資料!$H:$H, (MATCH(29, 輔助計算!$E$2:$E$801, 0)+1))), "") | H30: =IFERROR(INDEX(輔助計算!$D:$D, (MATCH(29, 輔助計算!$E$2:$E$801, 0)+1)), "") | I30: =IFERROR(IF(INDEX(ERP資料!$O:$O, (MATCH(29, 輔助計算!$E$2:$E$801, 0)+1))="","",INDEX(ERP資料!$O:$O, (MATCH(29, 輔助計算!$E$2:$E$801, 0)+1))), "") | J30: =IFERROR(IF(INDEX(輔助計算!$D:$D,(MATCH(29, 輔助計算!$E$2:$E$801, 0)+1))="","",INDEX(輔助計算!$D:$D,(MATCH(29, 輔助計算!$E$2:$E$801, 0)+1))*INDEX(ERP資料!$O:$O,(MATCH(29, 輔助計算!$E$2:$E$801, 0)+1))), "")
A31: =IFERROR(IF(INDEX(ERP資料!$B:$B, (MATCH(30, 輔助計算!$E$2:$E$801, 0)+1))="","",INDEX(ERP資料!$B:$B, (MATCH(30, 輔助計算!$E$2:$E$801, 0)+1))), "") | B31: =IFERROR(IF(INDEX(ERP資料!$A:$A, (MATCH(30, 輔助計算!$E$2:$E$801, 0)+1))="","",INDEX(ERP資料!$A:$A, (MATCH(30, 輔助計算!$E$2:$E$801, 0)+1))), "") | C31: =IFERROR(IF(INDEX(ERP資料!$S:$S, (MATCH(30, 輔助計算!$E$2:$E$801, 0)+1))="","",INDEX(ERP資料!$S:$S, (MATCH(30, 輔助計算!$E$2:$E$801, 0)+1))), "") | D31: =IFERROR(IF(INDEX(ERP資料!$E:$E, (MATCH(30, 輔助計算!$E$2:$E$801, 0)+1))="","",TRIM(INDEX(ERP資料!$E:$E, (MATCH(30, 輔助計算!$E$2:$E$801, 0)+1)))), "") | E31: =IFERROR(IF(INDEX(ERP資料!$F:$F, (MATCH(30, 輔助計算!$E$2:$E$801, 0)+1))="","",INDEX(ERP資料!$F:$F, (MATCH(30, 輔助計算!$E$2:$E$801, 0)+1))), "") | F31: =IFERROR(IF(INDEX(ERP資料!$G:$G, (MATCH(30, 輔助計算!$E$2:$E$801, 0)+1))="","",INDEX(ERP資料!$G:$G, (MATCH(30, 輔助計算!$E$2:$E$801, 0)+1))), "") | G31: =IFERROR(IF(INDEX(ERP資料!$H:$H, (MATCH(30, 輔助計算!$E$2:$E$801, 0)+1))="","",INDEX(ERP資料!$H:$H, (MATCH(30, 輔助計算!$E$2:$E$801, 0)+1))), "") | H31: =IFERROR(INDEX(輔助計算!$D:$D, (MATCH(30, 輔助計算!$E$2:$E$801, 0)+1)), "") | I31: =IFERROR(IF(INDEX(ERP資料!$O:$O, (MATCH(30, 輔助計算!$E$2:$E$801, 0)+1))="","",INDEX(ERP資料!$O:$O, (MATCH(30, 輔助計算!$E$2:$E$801, 0)+1))), "") | J31: =IFERROR(IF(INDEX(輔助計算!$D:$D,(MATCH(30, 輔助計算!$E$2:$E$801, 0)+1))="","",INDEX(輔助計算!$D:$D,(MATCH(30, 輔助計算!$E$2:$E$801, 0)+1))*INDEX(ERP資料!$O:$O,(MATCH(30, 輔助計算!$E$2:$E$801, 0)+1))), "")
A32: =IFERROR(IF(INDEX(ERP資料!$B:$B, (MATCH(31, 輔助計算!$E$2:$E$801, 0)+1))="","",INDEX(ERP資料!$B:$B, (MATCH(31, 輔助計算!$E$2:$E$801, 0)+1))), "") | B32: =IFERROR(IF(INDEX(ERP資料!$A:$A, (MATCH(31, 輔助計算!$E$2:$E$801, 0)+1))="","",INDEX(ERP資料!$A:$A, (MATCH(31, 輔助計算!$E$2:$E$801, 0)+1))), "") | C32: =IFERROR(IF(INDEX(ERP資料!$S:$S, (MATCH(31, 輔助計算!$E$2:$E$801, 0)+1))="","",INDEX(ERP資料!$S:$S, (MATCH(31, 輔助計算!$E$2:$E$801, 0)+1))), "") | D32: =IFERROR(IF(INDEX(ERP資料!$E:$E, (MATCH(31, 輔助計算!$E$2:$E$801, 0)+1))="","",TRIM(INDEX(ERP資料!$E:$E, (MATCH(31, 輔助計算!$E$2:$E$801, 0)+1)))), "") | E32: =IFERROR(IF(INDEX(ERP資料!$F:$F, (MATCH(31, 輔助計算!$E$2:$E$801, 0)+1))="","",INDEX(ERP資料!$F:$F, (MATCH(31, 輔助計算!$E$2:$E$801, 0)+1))), "") | F32: =IFERROR(IF(INDEX(ERP資料!$G:$G, (MATCH(31, 輔助計算!$E$2:$E$801, 0)+1))="","",INDEX(ERP資料!$G:$G, (MATCH(31, 輔助計算!$E$2:$E$801, 0)+1))), "") | G32: =IFERROR(IF(INDEX(ERP資料!$H:$H, (MATCH(31, 輔助計算!$E$2:$E$801, 0)+1))="","",INDEX(ERP資料!$H:$H, (MATCH(31, 輔助計算!$E$2:$E$801, 0)+1))), "") | H32: =IFERROR(INDEX(輔助計算!$D:$D, (MATCH(31, 輔助計算!$E$2:$E$801, 0)+1)), "") | I32: =IFERROR(IF(INDEX(ERP資料!$O:$O, (MATCH(31, 輔助計算!$E$2:$E$801, 0)+1))="","",INDEX(ERP資料!$O:$O, (MATCH(31, 輔助計算!$E$2:$E$801, 0)+1))), "") | J32: =IFERROR(IF(INDEX(輔助計算!$D:$D,(MATCH(31, 輔助計算!$E$2:$E$801, 0)+1))="","",INDEX(輔助計算!$D:$D,(MATCH(31, 輔助計算!$E$2:$E$801, 0)+1))*INDEX(ERP資料!$O:$O,(MATCH(31, 輔助計算!$E$2:$E$801, 0)+1))), "")
A33: =IFERROR(IF(INDEX(ERP資料!$B:$B, (MATCH(32, 輔助計算!$E$2:$E$801, 0)+1))="","",INDEX(ERP資料!$B:$B, (MATCH(32, 輔助計算!$E$2:$E$801, 0)+1))), "") | B33: =IFERROR(IF(INDEX(ERP資料!$A:$A, (MATCH(32, 輔助計算!$E$2:$E$801, 0)+1))="","",INDEX(ERP資料!$A:$A, (MATCH(32, 輔助計算!$E$2:$E$801, 0)+1))), "") | C33: =IFERROR(IF(INDEX(ERP資料!$S:$S, (MATCH(32, 輔助計算!$E$2:$E$801, 0)+1))="","",INDEX(ERP資料!$S:$S, (MATCH(32, 輔助計算!$E$2:$E$801, 0)+1))), "") | D33: =IFERROR(IF(INDEX(ERP資料!$E:$E, (MATCH(32, 輔助計算!$E$2:$E$801, 0)+1))="","",TRIM(INDEX(ERP資料!$E:$E, (MATCH(32, 輔助計算!$E$2:$E$801, 0)+1)))), "") | E33: =IFERROR(IF(INDEX(ERP資料!$F:$F, (MATCH(32, 輔助計算!$E$2:$E$801, 0)+1))="","",INDEX(ERP資料!$F:$F, (MATCH(32, 輔助計算!$E$2:$E$801, 0)+1))), "") | F33: =IFERROR(IF(INDEX(ERP資料!$G:$G, (MATCH(32, 輔助計算!$E$2:$E$801, 0)+1))="","",INDEX(ERP資料!$G:$G, (MATCH(32, 輔助計算!$E$2:$E$801, 0)+1))), "") | G33: =IFERROR(IF(INDEX(ERP資料!$H:$H, (MATCH(32, 輔助計算!$E$2:$E$801, 0)+1))="","",INDEX(ERP資料!$H:$H, (MATCH(32, 輔助計算!$E$2:$E$801, 0)+1))), "") | H33: =IFERROR(INDEX(輔助計算!$D:$D, (MATCH(32, 輔助計算!$E$2:$E$801, 0)+1)), "") | I33: =IFERROR(IF(INDEX(ERP資料!$O:$O, (MATCH(32, 輔助計算!$E$2:$E$801, 0)+1))="","",INDEX(ERP資料!$O:$O, (MATCH(32, 輔助計算!$E$2:$E$801, 0)+1))), "") | J33: =IFERROR(IF(INDEX(輔助計算!$D:$D,(MATCH(32, 輔助計算!$E$2:$E$801, 0)+1))="","",INDEX(輔助計算!$D:$D,(MATCH(32, 輔助計算!$E$2:$E$801, 0)+1))*INDEX(ERP資料!$O:$O,(MATCH(32, 輔助計算!$E$2:$E$801, 0)+1))), "")
A34: =IFERROR(IF(INDEX(ERP資料!$B:$B, (MATCH(33, 輔助計算!$E$2:$E$801, 0)+1))="","",INDEX(ERP資料!$B:$B, (MATCH(33, 輔助計算!$E$2:$E$801, 0)+1))), "") | B34: =IFERROR(IF(INDEX(ERP資料!$A:$A, (MATCH(33, 輔助計算!$E$2:$E$801, 0)+1))="","",INDEX(ERP資料!$A:$A, (MATCH(33, 輔助計算!$E$2:$E$801, 0)+1))), "") | C34: =IFERROR(IF(INDEX(ERP資料!$S:$S, (MATCH(33, 輔助計算!$E$2:$E$801, 0)+1))="","",INDEX(ERP資料!$S:$S, (MATCH(33, 輔助計算!$E$2:$E$801, 0)+1))), "") | D34: =IFERROR(IF(INDEX(ERP資料!$E:$E, (MATCH(33, 輔助計算!$E$2:$E$801, 0)+1))="","",TRIM(INDEX(ERP資料!$E:$E, (MATCH(33, 輔助計算!$E$2:$E$801, 0)+1)))), "") | E34: =IFERROR(IF(INDEX(ERP資料!$F:$F, (MATCH(33, 輔助計算!$E$2:$E$801, 0)+1))="","",INDEX(ERP資料!$F:$F, (MATCH(33, 輔助計算!$E$2:$E$801, 0)+1))), "") | F34: =IFERROR(IF(INDEX(ERP資料!$G:$G, (MATCH(33, 輔助計算!$E$2:$E$801, 0)+1))="","",INDEX(ERP資料!$G:$G, (MATCH(33, 輔助計算!$E$2:$E$801, 0)+1))), "") | G34: =IFERROR(IF(INDEX(ERP資料!$H:$H, (MATCH(33, 輔助計算!$E$2:$E$801, 0)+1))="","",INDEX(ERP資料!$H:$H, (MATCH(33, 輔助計算!$E$2:$E$801, 0)+1))), "") | H34: =IFERROR(INDEX(輔助計算!$D:$D, (MATCH(33, 輔助計算!$E$2:$E$801, 0)+1)), "") | I34: =IFERROR(IF(INDEX(ERP資料!$O:$O, (MATCH(33, 輔助計算!$E$2:$E$801, 0)+1))="","",INDEX(ERP資料!$O:$O, (MATCH(33, 輔助計算!$E$2:$E$801, 0)+1))), "") | J34: =IFERROR(IF(INDEX(輔助計算!$D:$D,(MATCH(33, 輔助計算!$E$2:$E$801, 0)+1))="","",INDEX(輔助計算!$D:$D,(MATCH(33, 輔助計算!$E$2:$E$801, 0)+1))*INDEX(ERP資料!$O:$O,(MATCH(33, 輔助計算!$E$2:$E$801, 0)+1))), "")
